Workbook
Name CapMonth: 'Absorption Schedule'!#REF!
Name CapPct: 'Absorption Schedule'!#REF!

Sheet INPUTS

Sheet T-12 Inputs
B2: Property: | D2: Date of Financials | E2: 46113
D4: 1 | E4: =+D4+1 -> 2 | F4: =+E4+1 -> 3 | G4: =+F4+1 -> 4 | H4: =+G4+1 -> 5 | I4: =+H4+1 -> 6 | J4: =+I4+1 -> 7 | K4: =+J4+1 -> 8 | L4: =+K4+1 -> 9 | ... O4: =+N4+1 -> 12 | S4: T-1 Trends | T4: T-3 Trends | U4: T-6 Trends | V4: T-9 Trends | W4: T-12 Trends
B5: REVENUE
A6: Line Item | B6: Notes | C6: Sub Notes | D6: =EOMONTH(E6,-1) -> 45808 | E6: =EOMONTH(F6,-1) -> 45838 | F6: =EOMONTH(G6,-1) -> 45869 | G6: =EOMONTH(H6,-1) -> 45900 | H6: =EOMONTH(I6,-1) -> 45930 | I6: =EOMONTH(J6,-1) -> 45961 | J6: =EOMONTH(K6,-1) -> 45991 | K6: =EOMONTH(L6,-1) -> 46022 | ... N6: =EOMONTH(O6,-1) -> 46112 | O6: =+E2 -> 46113 | Q6: Total
Q7: =IFERROR(SUM(D7:O7),"") -> 0 | S7: =+SUM(O7)*12 -> 0 | T7: =+SUM(M7:O7)*4 -> 0 | U7: =+SUM(J7:O7)*2 -> 0 | V7: =+SUM(G7:O7)/9*12 -> 0 | W7: =+SUM(D7:O7) -> 0
Q8: =IFERROR(SUM(D8:O8),"") -> 0 | S8: =+SUM(O8)*12 -> 0 | T8: =+SUM(M8:O8)*4 -> 0 | U8: =+SUM(J8:O8)*2 -> 0 | V8: =+SUM(G8:O8)/9*12 -> 0 | W8: =+SUM(D8:O8) -> 0 | Y8: {=+SUMPRODUCT(D7:O100*(A7:A100="GPR"))} -> 0
Q9: =IFERROR(SUM(D9:O9),"") -> 0 | S9: =+SUM(O9)*12 -> 0 | T9: =+SUM(M9:O9)*4 -> 0 | U9: =+SUM(J9:O9)*2 -> 0 | V9: =+SUM(G9:O9)/9*12 -> 0 | W9: =+SUM(D9:O9) -> 0
Q10: =IFERROR(SUM(D10:O10),"") -> 0 | S10: =+SUM(O10)*12 -> 0 | T10: =+SUM(M10:O10)*4 -> 0 | U10: =+SUM(J10:O10)*2 -> 0 | V10: =+SUM(G10:O10)/9*12 -> 0 | W10: =+SUM(D10:O10) -> 0
Q11: =IFERROR(SUM(D11:O11),"") -> 0 | S11: =+SUM(O11)*12 -> 0 | T11: =+SUM(M11:O11)*4 -> 0 | U11: =+SUM(J11:O11)*2 -> 0 | V11: =+SUM(G11:O11)/9*12 -> 0 | W11: =+SUM(D11:O11) -> 0
Q12: =IFERROR(SUM(D12:O12),"") -> 0 | S12: =+SUM(O12)*12 -> 0 | T12: =+SUM(M12:O12)*4 -> 0 | U12: =+SUM(J12:O12)*2 -> 0 | V12: =+SUM(G12:O12)/9*12 -> 0 | W12: =+SUM(D12:O12) -> 0
Q13: =IFERROR(SUM(D13:O13),"") -> 0 | S13: =+SUM(O13)*12 -> 0 | T13: =+SUM(M13:O13)*4 -> 0 | U13: =+SUM(J13:O13)*2 -> 0 | V13: =+SUM(G13:O13)/9*12 -> 0 | W13: =+SUM(D13:O13) -> 0
Q14: =IFERROR(SUM(D14:O14),"") -> 0 | S14: =+SUM(O14)*12 -> 0 | T14: =+SUM(M14:O14)*4 -> 0 | U14: =+SUM(J14:O14)*2 -> 0 | V14: =+SUM(G14:O14)/9*12 -> 0 | W14: =+SUM(D14:O14) -> 0
Q15: =IFERROR(SUM(D15:O15),"") -> 0 | S15: =+SUM(O15)*12 -> 0 | T15: =+SUM(M15:O15)*4 -> 0 | U15: =+SUM(J15:O15)*2 -> 0 | V15: =+SUM(G15:O15)/9*12 -> 0 | W15: =+SUM(D15:O15) -> 0
Q16: =IFERROR(SUM(D16:O16),"") -> 0 | S16: =+SUM(O16)*12 -> 0 | T16: =+SUM(M16:O16)*4 -> 0 | U16: =+SUM(J16:O16)*2 -> 0 | V16: =+SUM(G16:O16)/9*12 -> 0 | W16: =+SUM(D16:O16) -> 0
Q17: =IFERROR(SUM(D17:O17),"") -> 0 | S17: =+SUM(O17)*12 -> 0 | T17: =+SUM(M17:O17)*4 -> 0 | U17: =+SUM(J17:O17)*2 -> 0 | V17: =+SUM(G17:O17)/9*12 -> 0 | W17: =+SUM(D17:O17) -> 0
Q18: =IFERROR(SUM(D18:O18),"") -> 0 | S18: =+SUM(O18)*12 -> 0 | T18: =+SUM(M18:O18)*4 -> 0 | U18: =+SUM(J18:O18)*2 -> 0 | V18: =+SUM(G18:O18)/9*12 -> 0 | W18: =+SUM(D18:O18) -> 0
Q19: =IFERROR(SUM(D19:O19),"") -> 0 | S19: =+SUM(O19)*12 -> 0 | T19: =+SUM(M19:O19)*4 -> 0 | U19: =+SUM(J19:O19)*2 -> 0 | V19: =+SUM(G19:O19)/9*12 -> 0 | W19: =+SUM(D19:O19) -> 0
Q20: =IFERROR(SUM(D20:O20),"") -> 0 | S20: =+SUM(O20)*12 -> 0 | T20: =+SUM(M20:O20)*4 -> 0 | U20: =+SUM(J20:O20)*2 -> 0 | V20: =+SUM(G20:O20)/9*12 -> 0 | W20: =+SUM(D20:O20) -> 0
... Q58: =IFERROR(SUM(D58:O58),"") -> 0 | S58: =+SUM(O58)*12 -> 0 | T58: =+SUM(M58:O58)*4 -> 0 | U58: =+SUM(J58:O58)*2 -> 0 | V58: =+SUM(G58:O58)/9*12 -> 0 | W58: =+SUM(D58:O58) -> 0
Q59: =IFERROR(SUM(O59:O59),"") -> 0 | S59: =+SUM(O59)*12 -> 0 | T59: =+SUM(M59:O59)*4 -> 0 | U59: =+SUM(J59:O59)*2 -> 0 | V59: =+SUM(G59:O59)/9*12 -> 0 | W59: =+SUM(D59:O59) -> 0
Q60: =IFERROR(SUM(D60:O60),"") -> 0 | S60: =+SUM(O60)*12 -> 0 | T60: =+SUM(M60:O60)*4 -> 0 | U60: =+SUM(J60:O60)*2 -> 0 | V60: =+SUM(G60:O60)/9*12 -> 0 | W60: =+SUM(D60:O60) -> 0
Q61: =IFERROR(SUM(D61:O61),"") -> 0 | S61: =+SUM(O61)*12 -> 0 | T61: =+SUM(M61:O61)*4 -> 0 | U61: =+SUM(J61:O61)*2 -> 0 | V61: =+SUM(G61:O61)/9*12 -> 0 | W61: =+SUM(D61:O61) -> 0
Q62: =IFERROR(SUM(D62:O62),"") -> 0 | S62: =+SUM(O62)*12 -> 0 | T62: =+SUM(M62:O62)*4 -> 0 | U62: =+SUM(J62:O62)*2 -> 0 | V62: =+SUM(G62:O62)/9*12 -> 0 | W62: =+SUM(D62:O62) -> 0
Q63: =IFERROR(SUM(D63:O63),"") -> 0 | S63: =+SUM(O63)*12 -> 0 | T63: =+SUM(M63:O63)*4 -> 0 | U63: =+SUM(J63:O63)*2 -> 0 | V63: =+SUM(G63:O63)/9*12 -> 0 | W63: =+SUM(D63:O63) -> 0
Q64: =IFERROR(SUM(D64:O64),"") -> 0 | S64: =+SUM(O64)*12 -> 0 | T64: =+SUM(M64:O64)*4 -> 0 | U64: =+SUM(J64:O64)*2 -> 0 | V64: =+SUM(G64:O64)/9*12 -> 0 | W64: =+SUM(D64:O64) -> 0
Q65: =IFERROR(SUM(D65:O65),"") -> 0 | S65: =+SUM(O65)*12 -> 0 | T65: =+SUM(M65:O65)*4 -> 0 | U65: =+SUM(J65:O65)*2 -> 0 | V65: =+SUM(G65:O65)/9*12 -> 0 | W65: =+SUM(D65:O65) -> 0
Q66: =IFERROR(SUM(D66:O66),"") -> 0 | S66: =+SUM(O66)*12 -> 0 | T66: =+SUM(M66:O66)*4 -> 0 | U66: =+SUM(J66:O66)*2 -> 0 | V66: =+SUM(G66:O66)/9*12 -> 0 | W66: =+SUM(D66:O66) -> 0
Q67: =IFERROR(SUM(D67:O67),"") -> 0 | S67: =+SUM(O67)*12 -> 0 | T67: =+SUM(M67:O67)*4 -> 0 | U67: =+SUM(J67:O67)*2 -> 0 | V67: =+SUM(G67:O67)/9*12 -> 0 | W67: =+SUM(D67:O67) -> 0
Q68: =IFERROR(SUM(D68:O68),"") -> 0 | S68: =+SUM(O68)*12 -> 0 | T68: =+SUM(M68:O68)*4 -> 0 | U68: =+SUM(J68:O68)*2 -> 0 | V68: =+SUM(G68:O68)/9*12 -> 0 | W68: =+SUM(D68:O68) -> 0
Q69: =IFERROR(SUM(D69:O69),"") -> 0 | S69: =+SUM(O69)*12 -> 0 | T69: =+SUM(M69:O69)*4 -> 0 | U69: =+SUM(J69:O69)*2 -> 0 | V69: =+SUM(G69:O69)/9*12 -> 0 | W69: =+SUM(D69:O69) -> 0
Q70: =IFERROR(SUM(D70:O70),"") -> 0 | S70: =+SUM(O70)*12 -> 0 | T70: =+SUM(M70:O70)*4 -> 0 | U70: =+SUM(J70:O70)*2 -> 0 | V70: =+SUM(G70:O70)/9*12 -> 0 | W70: =+SUM(D70:O70) -> 0
Q71: =IFERROR(SUM(D71:O71),"") -> 0 | S71: =+SUM(O71)*12 -> 0 | T71: =+SUM(M71:O71)*4 -> 0 | U71: =+SUM(J71:O71)*2 -> 0 | V71: =+SUM(G71:O71)/9*12 -> 0 | W71: =+SUM(D71:O71) -> 0
... Q100: =IFERROR(SUM(D100:O100),"") -> 0 | S100: =+SUM(O100)*12 -> 0 | T100: =+SUM(M100:O100)*4 -> 0 | U100: =+SUM(J100:O100)*2 -> 0 | V100: =+SUM(G100:O100)/9*12 -> 0 | W100: =+SUM(D100:O100) -> 0
B101: Total | D101: =+SUM(D7:D100) -> 0 | E101: =+SUM(E7:E100) -> 0 | F101: =+SUM(F7:F100) -> 0 | G101: =+SUM(G7:G100) -> 0 | H101: =+SUM(H7:H100) -> 0 | I101: =+SUM(I7:I100) -> 0 | J101: =+SUM(J7:J100) -> 0 | K101: =+SUM(K7:K100) -> 0 | ... O101: =+SUM(O7:O100) -> 0 | Q101: =SUM(Q7:Q100) -> 0 | S101: =SUM(S7:S100) -> 0 | T101: =SUM(T7:T100) -> 0 | U101: =SUM(U7:U100) -> 0 | V101: =SUM(V7:V100) -> 0 | W101: =SUM(W7:W100) -> 0
P102: Check | Q102: =+Q101-SUM(D101:O101) -> 0
B104: EXPENSES | D104: =+D6 -> 45808 | E104: =+E6 -> 45838 | F104: =+F6 -> 45869 | G104: =+G6 -> 45900 | H104: =+H6 -> 45930 | I104: =+I6 -> 45961 | J104: =+J6 -> 45991 | K104: =+K6 -> 46022 | ... O104: =+O6 -> 46113 | S104: T-1 Trends | T104: T-3 Trends | U104: T-6 Trends | V104: T-9 Trends | W104: T-12 Trends
Q105: =IFERROR(SUM(D105:O105),"") -> 0 | S105: =+SUM(O105)*12 -> 0 | T105: =+SUM(M105:O105)*4 -> 0 | U105: =+SUM(J105:O105)*2 -> 0 | V105: =+SUM(G105:O105)/9*12 -> 0 | W105: =+SUM(D105:O105) -> 0
Q106: =IFERROR(SUM(D106:O106),"") -> 0 | S106: =+SUM(O106)*12 -> 0 | T106: =+SUM(M106:O106)*4 -> 0 | U106: =+SUM(J106:O106)*2 -> 0 | V106: =+SUM(G106:O106)/9*12 -> 0 | W106: =+SUM(D106:O106) -> 0
Q107: =IFERROR(SUM(D107:O107),"") -> 0 | S107: =+SUM(O107)*12 -> 0 | T107: =+SUM(M107:O107)*4 -> 0 | U107: =+SUM(J107:O107)*2 -> 0 | V107: =+SUM(G107:O107)/9*12 -> 0 | W107: =+SUM(D107:O107) -> 0
Q108: =IFERROR(SUM(D108:O108),"") -> 0 | S108: =+SUM(O108)*12 -> 0 | T108: =+SUM(M108:O108)*4 -> 0 | U108: =+SUM(J108:O108)*2 -> 0 | V108: =+SUM(G108:O108)/9*12 -> 0 | W108: =+SUM(D108:O108) -> 0
...

Sheet Other Income Assumptions
B2: Total Number of Units
B3: ='Rent Schedule'!$E$21 -> 0
B5: Code | C5: Line Item | D5: Fees | E5: =+'Absorption Schedule'!I25 -> 46204 | F5: =EOMONTH(E5,1) -> 46265 | G5: =EOMONTH(F5,1) -> 46295 | H5: =EOMONTH(G5,1) -> 46326 | I5: =EOMONTH(H5,1) -> 46356 | J5: =EOMONTH(I5,1) -> 46387 | K5: =EOMONTH(J5,1) -> 46418 | L5: =EOMONTH(K5,1) -> 46446 | M5: =EOMONTH(L5,1) -> 46477 | ... P5: =EOMONTH(O5,1) -> 46568 | Q5: Total | R5: Comments
C6: Utilities (RUBS) Water&Sewer | Q6: =SUM(E6:P6) -> 0
C7: Retail Income - CAM | Q7: =SUM(E7:P7) -> 0
C8: Garage Rent | Q8: =SUM(E8:P8) -> 0
C9: Storage Rent | Q9: =SUM(E9:P9) -> 0
C10: Pet Rent | Q10: =SUM(E10:P10) -> 0
C11: Other Rent | Q11: =SUM(E11:P11) -> 0
C12: Month-to-Month Premium | Q12: =SUM(E12:P12) -> 0
C13: Application Fees | Q13: =SUM(E13:P13) -> 0
C14: Administrative Fees | Q14: =SUM(E14:P14) -> 0
C15: Transfer Fees | Q15: =SUM(E15:P15) -> 0
C16: Pet Fees | Q16: =SUM(E16:P16) -> 0
C17: Utilities Reimbursement - Water | Q17: =SUM(E17:P17) -> 0
... C33: Other Fees | Q33: =SUM(E33:P33) -> 0
Q34: =SUM(E34:P34) -> 0
Q35: =SUM(E35:P35) -> 0
Q36: =SUM(E36:P36) -> 0
Q37: =SUM(E37:P37) -> 0
Q38: =SUM(E38:P38) -> 0
Q39: =SUM(E39:P39) -> 0
Q40: =SUM(E40:P40) -> 0
Q41: =SUM(E41:P41) -> 0
Q42: =SUM(E42:P42) -> 0
Q43: =SUM(E43:P43) -> 0
Q44: =SUM(E44:P44) -> 0
Q45: =SUM(E45:P45) -> 0
... Q101: =SUM(E101:P101) -> 0
B103: xx | C103: Total | E103: =SUM(E6:E101) -> 0 | F103: =SUM(F6:F101) -> 0 | G103: =SUM(G6:G101) -> 0 | H103: =SUM(H6:H101) -> 0 | I103: =SUM(I6:I101) -> 0 | J103: =SUM(J6:J101) -> 0 | K103: =SUM(K6:K101) -> 0 | L103: =SUM(L6:L101) -> 0 | ... P103: =SUM(P6:P101) -> 0 | Q103: =SUM(E103:P103) -> 0
Q105: =+Q103/B3 -> #DIV/0!
Q106: Per Unit

Sheet Payroll Schedule - Lease-Up
B5: Proposed Payroll Schedule | C5: =IF('Proforma (Annual)'!C2="",'Lease-Up Proforma'!C2,'Proforma (Annual)'!C2) -> 0
B6: Units | C6: ='Rent Schedule'!E31 -> 0
B9: TOTAL PAYROLL | C9: =SUM(J21,J34,F40,F51) -> 588812.8
B10: Per Unit | C10: =C9/C6 -> #DIV/0!
B13: Property Management Team | H13: 0.28
B14: Position | C14: FT/PT (Hrs) | D14: Salary | F14: Hourly Rate | G14: Payroll Prior to Burden | H14: Burden
B15: Community Manager | C15: 2080 | D15: 95000 | G15: =IF(D15>0, D15, C15*F15) -> 95000 | H15: =G15*$H$13 -> 26600
B16: Assistant Manager | C16: 2080 | F16: 25 | G16: =IF(D16>0, D16, C16*F16) -> 52000 | H16: =G16*$H$13 -> 14560
B17: Leasing Professional | C17: 2080 | F17: 20 | G17: =IF(D17>0, D17, C17*F17) -> 41600 | H17: =G17*$H$13 -> 11648
B18: Leasing Professional | C18: 2080 | F18: 19 | G18: =IF(D18>0, D18, C18*F18) -> 39520 | H18: =G18*$H$13 -> 11065.6
G19: =IF(D19>0, D19, C19*F19) -> 0 | H19: =G19*$H$13 -> 0
G20: =IF(D20>0, D20, C20*F20) -> 0 | H20: =G20*$H$13 -> 0
D21: Total Property Management Cost | G21: =SUM(G15:G20) -> 228120 | H21: =SUM(H15:H20) -> 63873.6 | J21: =SUM(G21:H21) -> 291993.6 | K21: Total
B24: Maintenance Team | H24: =H13 -> 0.28
B25: Position | C25: FT/PT (Hrs) | D25: Salary | F25: Hourly Rate | G25: Payroll Prior to Burden | H25: Burden
B26: Service Supervisor | C26: 2080 | F26: 34 | G26: =IF(D26>0, D26, C26*F26) -> 70720 | H26: =G26*$H$13 -> 19801.6
B27: Service Technician | C27: 2080 | F27: 22.5 | G27: =IF(D27>0, D27, C27*F27) -> 46800 | H27: =G27*$H$13 -> 13104
B28: Make-Ready | C28: 2080 | F28: 20 | G28: =IF(D28>0, D28, C28*F28) -> 41600 | H28: =G28*$H$13 -> 11648
B29: Porter | C29: 2080 | F29: 19 | G29: =IF(D29>0, D29, C29*F29) -> 39520 | H29: =G29*$H$13 -> 11065.6
G30: =IF(D30>0, D30, C30*F30) -> 0 | H30: =G30*$H$13 -> 0
G31: =IF(D31>0, D31, C31*F31) -> 0 | H31: =G31*$H$13 -> 0
G32: =IF(D32>0, D32, C32*F32) -> 0 | H32: =G32*$H$13 -> 0
G33: =IF(D33>0, D33, C33*F33) -> 0 | H33: =G33*$H$13 -> 0
D34: Total Maintenance Team Cost | G34: =SUM(G26:G33) -> 198640 | H34: =SUM(H26:H33) -> 55619.2 | J34: =SUM(G34:H34) -> 254259.2 | K34: Total
B37: Leasing Bonuses
B38: Average New Lease/Renewal Bonus: | D38: 185
B39: New Lease/Renewal Percentage Pay-Out: | D39: 0.8
B40: Total Leasing Bonus Cost | D40: =(C6*D38*D39)*(1+H13) -> 0 | F40: =D40 -> 0 | G40: Total
B42: Team Bonuses | C42: Bonus Potential | D42: Burden
B43: =+B15 -> Community Manager | C43: =D15*0.15 -> 14250 | D43: =+C43*$H$24 -> 3990
B44: =+B16 -> Assistant Manager | C44: 4000 | D44: =+C44*$H$24 -> 1120
B46: =+B26 -> Service Supervisor | C46: 6000 | D46: =+C46*$H$24 -> 1680
B47: =+B27 -> Service Technician | C47: 4000 | D47: =+C47*$H$24 -> 1120
B48: =+B28 -> Make-Ready | C48: 3000 | D48: =+C48*$H$24 -> 840
B49: =+B29 -> Porter | C49: 2000 | D49: =+C49*$H$24 -> 560
D50: =+C50*$H$24 -> 0
B51: Total | C51: =SUM(C43:C50) -> 33250 | D51: =SUM(D43:D50) -> 9310 | F51: =SUM(C51:D51) -> 42560 | G51: Total

Sheet Payroll Schedule
B5: Proposed Payroll Schedule | C5: =IF('Proforma (Annual)'!C2="",'Lease-Up Proforma'!C2,'Proforma (Annual)'!C2) -> 0
B6: Units | C6: ='Rent Schedule'!E31 -> 0
B9: TOTAL PAYROLL | C9: =SUM(J21,J34,F40,F51) -> 572412.5
B10: Per Unit | C10: =C9/C6 -> #DIV/0!
B13: Property Management Team | H13: 0.25
B14: Position | C14: FT/PT (Hrs) | D14: Salary | F14: Hourly Rate | G14: Payroll Prior to Burden | H14: Burden
B15: Community Manager | C15: 2080 | D15: 95000 | G15: =IF(D15>0, D15, C15*F15) -> 95000 | H15: =G15*$H$13 -> 23750
B16: Assistant Manager | C16: 2080 | F16: 24 | G16: =IF(D16>0, D16, C16*F16) -> 49920 | H16: =G16*$H$13 -> 12480
B17: Leasing Professional | C17: 2080 | F17: 20 | G17: =IF(D17>0, D17, C17*F17) -> 41600 | H17: =G17*$H$13 -> 10400
B18: Leasing Professional | C18: 2080 | F18: 19 | G18: =IF(D18>0, D18, C18*F18) -> 39520 | H18: =G18*$H$13 -> 9880
G19: =IF(D19>0, D19, C19*F19) -> 0 | H19: =G19*$H$13 -> 0
G20: =IF(D20>0, D20, C20*F20) -> 0 | H20: =G20*$H$13 -> 0
D21: Total Property Management Cost | G21: =SUM(G15:G20) -> 226040 | H21: =SUM(H15:H20) -> 56510 | J21: =SUM(G21:H21) -> 282550 | K21: Total
B24: Maintenance Team | H24: =H13 -> 0.25
B25: Position | C25: FT/PT (Hrs) | D25: Salary | F25: Hourly Rate | G25: Payroll Prior to Burden | H25: Burden
B26: Service Supervisor | C26: 2080 | F26: 34 | G26: =IF(D26>0, D26, C26*F26) -> 70720 | H26: =G26*$H$13 -> 17680
B27: Service Technician | C27: 2080 | F27: 22.5 | G27: =IF(D27>0, D27, C27*F27) -> 46800 | H27: =G27*$H$13 -> 11700
B28: Make-Ready | C28: 2080 | F28: 20 | G28: =IF(D28>0, D28, C28*F28) -> 41600 | H28: =G28*$H$13 -> 10400
B29: Porter | C29: 2080 | F29: 19 | G29: =IF(D29>0, D29, C29*F29) -> 39520 | H29: =G29*$H$13 -> 9880
G30: =IF(D30>0, D30, C30*F30) -> 0 | H30: =G30*$H$13 -> 0
G31: =IF(D31>0, D31, C31*F31) -> 0 | H31: =G31*$H$13 -> 0
G32: =IF(D32>0, D32, C32*F32) -> 0 | H32: =G32*$H$13 -> 0
G33: =IF(D33>0, D33, C33*F33) -> 0 | H33: =G33*$H$13 -> 0
D34: Total Maintenance Team Cost | G34: =SUM(G26:G33) -> 198640 | H34: =SUM(H26:H33) -> 49660 | J34: =SUM(G34:H34) -> 248300 | K34: Total
B37: Leasing Bonuses
B38: Average New Lease/Renewal Bonus: | D38: 150
B39: New Lease/Renewal Percentage Pay-Out: | D39: 0.9
B40: Total Leasing Bonus Cost | D40: =(C6*D38*D39)*(1+H13) -> 0 | F40: =D40 -> 0 | G40: Total
B42: Team Bonuses | C42: Bonus Potential | D42: Burden
B43: =+B15 -> Community Manager | C43: =D15*0.15 -> 14250 | D43: =+C43*$H$24 -> 3562.5
B44: =+B16 -> Assistant Manager | C44: 4000 | D44: =+C44*$H$24 -> 1000
B46: =+B26 -> Service Supervisor | C46: 6000 | D46: =+C46*$H$24 -> 1500
B47: =+B27 -> Service Technician | C47: 4000 | D47: =+C47*$H$24 -> 1000
B48: =+B28 -> Make-Ready | C48: =IF(B48>0,3000,"") -> 3000 | D48: =IF(C48>0,C48*$H$24,"") -> 750
B49: =+B29 -> Porter | C49: =IF(B49>0,2000,"") -> 2000 | D49: =IF(C49>0,C49*$H$24,"") -> 500
C50: =IF(B50>0,2000,"") | D50: =IF(C50="<>0",C50*$H$24,"")
B51: Total | C51: =SUM(C43:C50) -> 33250 | D51: =SUM(D43:D50) -> 8312.5 | F51: =SUM(C51:D51) -> 41562.5 | G51: Total

Sheet G&A Assumptions
B2: Total Number of Units
B3: ='Rent Schedule'!$E$21 -> 0
B5: Code | C5: Line Item | D5: Fixed Costs | E5: =+'Absorption Schedule'!I25 -> 46204 | F5: =EOMONTH(E5,1 ) -> 46265 | G5: =EOMONTH(F5,1 ) -> 46295 | H5: =EOMONTH(G5,1 ) -> 46326 | I5: =EOMONTH(H5,1 ) -> 46356 | J5: =EOMONTH(I5,1 ) -> 46387 | K5: =EOMONTH(J5,1 ) -> 46418 | L5: =EOMONTH(K5,1 ) -> 46446 | M5: =EOMONTH(L5,1 ) -> 46477 | ... P5: =EOMONTH(O5,1 ) -> 46568 | Q5: Total | R5: Comments
C6: Bank Charges | Q6: =SUM(E6:P6) -> 0
C7: Credit Processing | Q7: =SUM(E7:P7) -> 0
C8: Eviction Costs | Q8: =SUM(E8:P8) -> 0
C9: Legal Services | Q9: =SUM(E9:P9) -> 0
C10: Delivery Services | Q10: =SUM(E10:P10) -> 0
C11: Apartment Association Fees | Q11: =SUM(E11:P11) -> 0
C12: Licenses and Permits | Q12: =SUM(E12:P12) -> 0
C13: Forms | Q13: =SUM(E13:P13) -> 0
C14: Postage | Q14: =SUM(E14:P14) -> 0
C15: General Office Supplies | Q15: =SUM(E15:P15) -> 0
C16: Office Equipment | Q16: =SUM(E16:P16) -> 0
C17: Leasing/Management Software | Q17: =SUM(E17:P17) -> 0
... C25: Misc. Fees/Expenses | Q25: =SUM(E25:P25) -> 0
Q26: =SUM(E26:P26) -> 0
Q27: =SUM(E27:P27) -> 0
Q28: =SUM(E28:P28) -> 0
Q29: =SUM(E29:P29) -> 0
Q30: =SUM(E30:P30) -> 0
Q31: =SUM(E31:P31) -> 0
Q32: =SUM(E32:P32) -> 0
Q33: =SUM(E33:P33) -> 0
Q34: =SUM(E34:P34) -> 0
Q35: =SUM(E35:P35) -> 0
Q36: =SUM(E36:P36) -> 0
Q37: =SUM(E37:P37) -> 0
... Q101: =SUM(E101:P101) -> 0
B103: xx | C103: Total | E103: =SUM(E6:$E$101) -> 0 | F103: =SUM(F6:$F$101) -> 0 | G103: =SUM(G6:$G$101) -> 0 | H103: =SUM(H6:$H$101) -> 0 | I103: =SUM(I6:$I$101) -> 0 | J103: =SUM(J6:$J$101) -> 0 | K103: =SUM(K6:$K$101) -> 0 | L103: =SUM(L6:$L$101) -> 0 | M103: =SUM(M6:$M$101) -> 0 | N103: =SUM(N6:$N$101) -> 0 | O103: =SUM(O6:$O$101) -> 0 | P103: =SUM(P6:$P$101) -> 0 | Q103: =SUM($E$103:$P$103) -> 0
Q105: =Q103/B3 -> #DIV/0!
Q106: Per Unit

Sheet Marketing Stack - Lease-Up
B2: Total Number of Units
B3: ='Rent Schedule'!E31 -> 0
B5: Code | C5: Service | D5: Level | E5: =+'Absorption Schedule'!I25 -> 46204 | F5: =EOMONTH(E5,1 ) -> 46265 | G5: =EOMONTH(F5,1 ) -> 46295 | H5: =EOMONTH(G5,1 ) -> 46326 | I5: =EOMONTH(H5,1 ) -> 46356 | J5: =EOMONTH(I5,1 ) -> 46387 | K5: =EOMONTH(J5,1 ) -> 46418 | L5: =EOMONTH(K5,1 ) -> 46446 | M5: =EOMONTH(L5,1 ) -> 46477 | ... P5: =EOMONTH(O5,1 ) -> 46568 | Q5: Total | R5: Comments
B6: Marketing | C6: Apts.com | D6: Platinum+ | E6: =+INDEX('Marketing List - Dropdowns'!G5:I12,MATCH('Marketing Stack - Lease-Up'!D6,'Marketing List - Dropdowns'!F5:F12,0),MATCH('Marketing List - Dropdowns'!E4,'Marketing List - Dropdowns'!G4:I4,0)) -> 1625 | F6: =+E6 -> 1625 | G6: =+F6 -> 1625 | H6: =+G6 -> 1625 | I6: =+H6 -> 1625 | J6: =+I6 -> 1625 | K6: =+J6 -> 1625 | L6: =+K6 -> 1625 | M6: =+L6 -> 1625 | ... P6: =+O6 -> 1625 | Q6: =SUM(E6:P6) -> 19500
B7: Marketing | C7: Pay Per Click | D7: 2000 | E7: =+D7 -> 2000 | F7: =+E7 -> 2000 | G7: =+F7 -> 2000 | H7: =+G7 -> 2000 | I7: =+H7 -> 2000 | J7: =+I7 -> 2000 | K7: =+J7 -> 2000 | L7: =+K7 -> 2000 | ... P7: =+O7 -> 2000 | Q7: =+SUM(E7:P7) -> 24000
B8: Marketing | C8: Geofence Campaign | D8: Yes | E8: =+IF(D8="Yes",'Marketing List - Dropdowns'!$P$4,0) -> 350 | F8: =+E8 -> 350 | G8: =+F8 -> 350 | H8: =+G8 -> 350 | I8: =+H8 -> 350 | J8: =+I8 -> 350 | K8: =+J8 -> 350 | L8: =+K8 -> 350 | M8: =+L8 -> 350 | ... P8: =+O8 -> 350 | Q8: =+SUM(E8:P8) -> 4200
B9: Marketing | C9: Digital Direct Mail | D9: Yes | E9: 0 | F9: 0 | G9: 350 | H9: =E9 -> 0 | I9: =F9 -> 0 | J9: =G9 -> 350 | K9: =H9 -> 0 | L9: =I9 -> 0 | M9: =G9 -> 350 | N9: =H9 -> 0 | O9: =I9 -> 0 | P9: =J9 -> 350 | Q9: =+SUM(E9:P9) -> 1400
B10: Marketing | C10: Retargeting | D10: Yes | E10: =+IF(D10="Yes",'Marketing List - Dropdowns'!$S$4,0) -> 300 | F10: =+E10 -> 300 | G10: =+F10 -> 300 | H10: =+G10 -> 300 | I10: =+H10 -> 300 | J10: =+I10 -> 300 | K10: =+J10 -> 300 | L10: =+K10 -> 300 | M10: =+L10 -> 300 | ... P10: =+O10 -> 300 | Q10: =+SUM(E10:P10) -> 3600
B11: Marketing | C11: Apartment List
B12: Referral Fees | C12: Apartment List (Monthly Cost) | D12: Yes | E12: =IF(D12="Yes",'Marketing List - Dropdowns'!G25,0) -> 63 | F12: =E12 -> 63 | G12: =F12 -> 63 | H12: =G12 -> 63 | I12: =H12 -> 63 | J12: =I12 -> 63 | K12: =J12 -> 63 | L12: =K12 -> 63 | M12: =L12 -> 63 | ... P12: =O12 -> 63 | Q12: =+SUM(E12:P12) -> 756
B13: Referral Fees | C13: Apartment List (estimated leases per month) | D13: 2 | E13: =+INDEX('Marketing List - Dropdowns'!G19:G24,MATCH('Marketing Stack - Lease-Up'!D13,'Marketing List - Dropdowns'!F19:F31,0)) -> 818 | F13: =+E13 -> 818 | G13: =+F13 -> 818 | H13: =+G13 -> 818 | I13: =+H13 -> 818 | J13: =+I13 -> 818 | K13: =+J13 -> 818 | L13: =+K13 -> 818 | M13: =+L13 -> 818 | ... P13: =+O13 -> 818 | Q13: =+SUM(E13:P13) -> 9816 | R13: Referral fee is $409/lease plus monthly cost of $63.
B14: Referral Fees | C14: RentGrata
B15: Referral Fees | C15: RentGrata (Monthly Cost) | D15: Yes | E15: =IF(D15="Yes",'Marketing List - Dropdowns'!$G$37,0) -> 380 | F15: =E15 -> 380 | G15: =F15 -> 380 | H15: =G15 -> 380 | I15: =H15 -> 380 | J15: =I15 -> 380 | K15: =J15 -> 380 | L15: =K15 -> 380 | M15: =L15 -> 380 | ... P15: =O15 -> 380 | Q15: =+SUM(E15:P15) -> 4560
B16: Referral Fees | C16: RentGrata Referral Cost (estimated leases per month) | D16: 2 | E16: =+INDEX('Marketing List - Dropdowns'!G31:G36,MATCH('Marketing Stack - Lease-Up'!D16,'Marketing List - Dropdowns'!F31:F36,0)) -> 500 | F16: =E16 -> 500 | G16: =F16 -> 500 | H16: =G16 -> 500 | I16: =H16 -> 500 | J16: =I16 -> 500 | K16: =J16 -> 500 | L16: =K16 -> 500 | M16: =L16 -> 500 | ... P16: =O16 -> 500 | Q16: =+SUM(E16:P16) -> 6000
B17: Marketing | C17: Apartment Ratings (annual rate) $100 set up + $350/mo | Q17: =+SUM(E17:P17) -> 0
B18: Marketing | C18: Better Bot ($200 set up fee) | D18: Yes | E18: 229 | F18: 229 | G18: 229 | H18: 229 | I18: 229 | J18: 229 | K18: 229 | L18: 229 | M18: 229 | N18: 229 | O18: 229 | P18: 229 | Q18: =+SUM(E18:P18) -> 2748
B19: Marketing | C19: Virtual Tours Monthly Hosting Fee | Q19: =+SUM(E19:P19) -> 0
B20: Marketing | C20: Kingsley Reputation | D20: Yes | E20: =+IF(D20="Yes",'Marketing List - Dropdowns'!$N$18,0) -> 55 | F20: =+E20 -> 55 | G20: =+F20 -> 55 | H20: =+G20 -> 55 | I20: =+H20 -> 55 | J20: =+I20 -> 55 | K20: =+J20 -> 55 | L20: =+K20 -> 55 | M20: =+L20 -> 55 | ... P20: =+O20 -> 55 | Q20: =+SUM(E20:P20) -> 660
B21: Marketing | C21: Kingsley Surveys | D21: Yes | E21: =+IF(D21="Yes",'Marketing List - Dropdowns'!Q18*'Marketing Stack - Lease-Up'!$B$3,0) -> 0 | F21: =+E21 -> 0 | G21: =+F21 -> 0 | H21: =+G21 -> 0 | I21: =+H21 -> 0 | J21: =+I21 -> 0 | K21: =+J21 -> 0 | L21: =+K21 -> 0 | M21: =+L21 -> 0 | ... P21: =+O21 -> 0 | Q21: =+SUM(E21:P21) -> 0
B22: Marketing | C22: Canva | D22: Yes | E22: 400 | Q22: =+SUM(E22:P22) -> 400
B23: Marketing | Q23: =+SUM(E23:P23) -> 0
B24: Marketing | C24: Engrain Suite
B25: Marketing | C25: Engrain (Site Map) | D25: Yes | E25: =+IF(D25="Yes",'Marketing List - Dropdowns'!$T$19,0) -> 81 | F25: =+E25 -> 81 | G25: =+F25 -> 81 | H25: =+G25 -> 81 | I25: =+H25 -> 81 | J25: =+I25 -> 81 | K25: =+J25 -> 81 | L25: =+K25 -> 81 | M25: =+L25 -> 81 | ... P25: =+O25 -> 81 | Q25: =+SUM(E25:P25) -> 972
B26: Marketing | C26: Engrain (Site Map) - One Time Set Up Cost | D26: Yes | E26: =+IF(D26="Yes",'Marketing List - Dropdowns'!T18,0) -> 375 | F26: 0 | G26: 0 | H26: 0 | I26: 0 | J26: 0 | K26: 0 | L26: 0 | M26: 0 | N26: 0 | O26: 0 | P26: 0 | Q26: =+SUM(E26:P26) -> 375
B27: Marketing | C27: Engrain (Asset Intelligence) | D27: Yes | E27: =+IF(D27="Yes",'Marketing List - Dropdowns'!$W$19,0) -> 199 | F27: =+E27 -> 199 | G27: =+F27 -> 199 | H27: =+G27 -> 199 | I27: =+H27 -> 199 | J27: =+I27 -> 199 | K27: =+J27 -> 199 | L27: =+K27 -> 199 | M27: =+L27 -> 199 | ... P27: =+O27 -> 199 | Q27: =+SUM(E27:P27) -> 2388
B28: Marketing | C28: Engrain (Asset Intelligence) - One Time Set Up Cost | D28: Yes | E28: =+IF(D28="Yes",'Marketing List - Dropdowns'!$W$18,0) -> 600 | F28: 0 | G28: 0 | H28: 0 | I28: 0 | J28: 0 | K28: 0 | L28: 0 | M28: 0 | N28: 0 | O28: 0 | P28: 0 | Q28: =+SUM(E28:P28) -> 600
B29: Resident Retention | C29: Resident Retention/Prospect Experience | E29: 2000 | F29: =E29 -> 2000 | G29: =F29 -> 2000 | H29: =G29 -> 2000 | I29: =H29 -> 2000 | J29: =I29 -> 2000 | K29: =J29 -> 2000 | L29: =K29 -> 2000 | M29: =L29 -> 2000 | ... P29: =O29 -> 2000 | Q29: =+SUM(E29:P29) -> 24000
B30: Locator Fees | C30: Locators | E30: 2750 | F30: =E30 -> 2750 | G30: =F30 -> 2750 | H30: =G30 -> 2750 | I30: =H30 -> 2750 | J30: =I30 -> 2750 | K30: =J30 -> 2750 | L30: =K30 -> 2750 | M30: =L30 -> 2750 | ... P30: =O30 -> 2750 | Q30: =+SUM(E30:P30) -> 33000
B31: Marketing | Q31: =+SUM(E31:P31) -> 0
B32: Marketing
B33: Marketing
B34: Marketing
B35: Marketing
B36: Marketing
B37: Marketing
C38: Marketing Support Services | D38: 325 | E38: =$D$38 -> 325 | F38: =$D$38 -> 325 | G38: =$D$38 -> 325 | H38: =$D$38 -> 325 | I38: =$D$38 -> 325 | J38: =$D$38 -> 325 | K38: =$D$38 -> 325 | L38: =$D$38 -> 325 | ... P38: =$D$38 -> 325 | Q38: =+SUM(E38:P38) -> 3900
E39: =SUM(E6:E38) -> 13050 | F39: =SUM(F6:F38) -> 11675 | G39: =SUM(G6:G38) -> 12025 | H39: =SUM(H6:H38) -> 11675 | I39: =SUM(I6:I38) -> 11675 | J39: =SUM(J6:J38) -> 12025 | K39: =SUM(K6:K38) -> 11675 | L39: =SUM(L6:L38) -> 11675 | ... Q39: =SUM(Q6:Q38) -> 142875
Q41: =+Q39/B3 -> #DIV/0!
Q42: Per Unit

Sheet Marketing Stack
B2: Total Number of Units
B3: ='Rent Schedule'!E31 -> 0
B5: Code | C5: Service | D5: Level | E5: =+'Absorption Schedule'!I25 -> 46204 | F5: =EOMONTH(E5,1 ) -> 46265 | G5: =EOMONTH(F5,1 ) -> 46295 | H5: =EOMONTH(G5,1 ) -> 46326 | I5: =EOMONTH(H5,1 ) -> 46356 | J5: =EOMONTH(I5,1 ) -> 46387 | K5: =EOMONTH(J5,1 ) -> 46418 | L5: =EOMONTH(K5,1 ) -> 46446 | M5: =EOMONTH(L5,1 ) -> 46477 | ... P5: =EOMONTH(O5,1 ) -> 46568 | Q5: Total | R5: Comments
B6: Marketing | C6: Apts.com | D6: Platinum+ | E6: =+INDEX('Marketing List - Dropdowns'!G5:I12,MATCH('Marketing Stack'!D6,'Marketing List - Dropdowns'!F5:F12,0),MATCH('Marketing List - Dropdowns'!E4,'Marketing List - Dropdowns'!G4:I4,0)) -> 1625 | F6: =+E6 -> 1625 | G6: =+F6 -> 1625 | H6: =+G6 -> 1625 | I6: =+H6 -> 1625 | J6: =+I6 -> 1625 | K6: =+J6 -> 1625 | L6: =+K6 -> 1625 | M6: =+L6 -> 1625 | ... P6: =+O6 -> 1625 | Q6: =SUM(E6:P6) -> 19500
B7: Marketing | C7: Pay Per Click | D7: 3000 | E7: =+D7 -> 3000 | F7: =+E7 -> 3000 | G7: =+F7 -> 3000 | H7: =+G7 -> 3000 | I7: =+H7 -> 3000 | J7: =+I7 -> 3000 | K7: =+J7 -> 3000 | L7: =+K7 -> 3000 | ... P7: =+O7 -> 3000 | Q7: =+SUM(E7:P7) -> 36000
B8: Marketing | C8: Geofence Campaign | D8: Yes | E8: =+IF(D8="Yes",'Marketing List - Dropdowns'!$P$4,0) -> 350 | F8: =+E8 -> 350 | G8: =+F8 -> 350 | H8: =+G8 -> 350 | I8: =+H8 -> 350 | J8: =+I8 -> 350 | K8: =+J8 -> 350 | L8: =+K8 -> 350 | M8: =+L8 -> 350 | ... P8: =+O8 -> 350 | Q8: =+SUM(E8:P8) -> 4200
B9: Marketing | C9: Digital Direct Mail | D9: Yes | E9: 0 | F9: 0 | G9: 350 | H9: =E9 -> 0 | I9: =F9 -> 0 | J9: =G9 -> 350 | K9: =H9 -> 0 | L9: =I9 -> 0 | M9: =G9 -> 350 | N9: =H9 -> 0 | O9: =I9 -> 0 | P9: =J9 -> 350 | Q9: =+SUM(E9:P9) -> 1400
B10: Marketing | C10: Retargeting | D10: Yes | E10: =+IF(D10="Yes",'Marketing List - Dropdowns'!$S$4,0) -> 300 | F10: =+E10 -> 300 | G10: =+F10 -> 300 | H10: =+G10 -> 300 | I10: =+H10 -> 300 | J10: =+I10 -> 300 | K10: =+J10 -> 300 | L10: =+K10 -> 300 | M10: =+L10 -> 300 | ... P10: =+O10 -> 300 | Q10: =+SUM(E10:P10) -> 3600
B11: Marketing | C11: Apartment List
B12: Referral Fees | C12: Apartment List (Monthly Cost) | D12: No | E12: =IF(D12="Yes",'Marketing List - Dropdowns'!G25,0) -> 0 | F12: =E12 -> 0 | G12: =F12 -> 0 | H12: =G12 -> 0 | I12: =H12 -> 0 | J12: =I12 -> 0 | K12: =J12 -> 0 | L12: =K12 -> 0 | M12: =L12 -> 0 | ... P12: =O12 -> 0 | Q12: =+SUM(E12:P12) -> 0
B13: Referral Fees | C13: Apartment List (estimated leases per month) | D13: 0 | E13: =+INDEX('Marketing List - Dropdowns'!G19:G24,MATCH('Marketing Stack'!D13,'Marketing List - Dropdowns'!F19:F31,0)) -> 0 | F13: =+E13 -> 0 | G13: =+F13 -> 0 | H13: =+G13 -> 0 | I13: =+H13 -> 0 | J13: =+I13 -> 0 | K13: =+J13 -> 0 | L13: =+K13 -> 0 | M13: =+L13 -> 0 | ... P13: =+O13 -> 0 | Q13: =+SUM(E13:P13) -> 0 | R13: =IF(D12="yes", "Referral fee is $409/lease plus monthly cost of $63.","")
B14: Referral Fees | C14: RentGrata
B15: Referral Fees | C15: RentGrata (Monthly Cost) | D15: No | E15: =IF(D15="Yes",'Marketing List - Dropdowns'!$G$37,0) -> 0 | F15: =E15 -> 0 | G15: =F15 -> 0 | H15: =G15 -> 0 | I15: =H15 -> 0 | J15: =I15 -> 0 | K15: =J15 -> 0 | L15: =K15 -> 0 | M15: =L15 -> 0 | ... P15: =O15 -> 0 | Q15: =+SUM(E15:P15) -> 0
B16: Referral Fees | C16: RentGrata Referral Cost (estimated leases per month) | D16: 0 | E16: =+INDEX('Marketing List - Dropdowns'!G31:G36,MATCH('Marketing Stack'!D16,'Marketing List - Dropdowns'!F31:F36,0)) -> 0 | F16: =E16 -> 0 | G16: =F16 -> 0 | H16: =G16 -> 0 | I16: =H16 -> 0 | J16: =I16 -> 0 | K16: =J16 -> 0 | L16: =K16 -> 0 | M16: =L16 -> 0 | ... P16: =O16 -> 0 | Q16: =+SUM(E16:P16) -> 0
B17: Marketing | C17: Apartment Ratings (annual rate) $100 set up + $350/mo | Q17: =+SUM(E17:P17) -> 0
B18: Marketing | C18: Better Bot ($200 set up fee) | D18: No | Q18: =+SUM(E18:P18) -> 0
B19: Marketing | C19: Virtual Tours Monthly Hosting Fee | Q19: =+SUM(E19:P19) -> 0
B20: Marketing | C20: Kingsley Reputation | D20: Yes | E20: =+IF(D20="Yes",'Marketing List - Dropdowns'!$N$18,0) -> 55 | F20: =+E20 -> 55 | G20: =+F20 -> 55 | H20: =+G20 -> 55 | I20: =+H20 -> 55 | J20: =+I20 -> 55 | K20: =+J20 -> 55 | L20: =+K20 -> 55 | M20: =+L20 -> 55 | ... P20: =+O20 -> 55 | Q20: =+SUM(E20:P20) -> 660
B21: Marketing | C21: Kingsley Surveys | D21: Yes | E21: =+IF(D21="Yes",'Marketing List - Dropdowns'!Q18*'Marketing Stack'!$B$3,0) -> 0 | F21: =+E21 -> 0 | G21: =+F21 -> 0 | H21: =+G21 -> 0 | I21: =+H21 -> 0 | J21: =+I21 -> 0 | K21: =+J21 -> 0 | L21: =+K21 -> 0 | M21: =+L21 -> 0 | ... P21: =+O21 -> 0 | Q21: =+SUM(E21:P21) -> 0
B22: Marketing | C22: Canva | D22: Yes | E22: 400 | Q22: =+SUM(E22:P22) -> 400
B23: Marketing | Q23: =+SUM(E23:P23) -> 0
B24: Marketing | C24: Engrain Suite
B25: Marketing | C25: Engrain (Site Map) | D25: Yes | E25: =+IF(D25="Yes",'Marketing List - Dropdowns'!$T$19,0) -> 81 | F25: =+E25 -> 81 | G25: =+F25 -> 81 | H25: =+G25 -> 81 | I25: =+H25 -> 81 | J25: =+I25 -> 81 | K25: =+J25 -> 81 | L25: =+K25 -> 81 | M25: =+L25 -> 81 | ... P25: =+O25 -> 81 | Q25: =+SUM(E25:P25) -> 972
B26: Marketing | C26: Engrain (Site Map) - One Time Set Up Cost | D26: No | E26: =+IF(D26="Yes",'Marketing List - Dropdowns'!T18,0) -> 0 | F26: 0 | G26: 0 | H26: 0 | I26: 0 | J26: 0 | K26: 0 | L26: 0 | M26: 0 | N26: 0 | O26: 0 | P26: 0 | Q26: =+SUM(E26:P26) -> 0
B27: Marketing | C27: Engrain (Asset Intelligence) | D27: No | E27: =+IF(D27="Yes",'Marketing List - Dropdowns'!$W$19,0) -> 0 | F27: =+E27 -> 0 | G27: =+F27 -> 0 | H27: =+G27 -> 0 | I27: =+H27 -> 0 | J27: =+I27 -> 0 | K27: =+J27 -> 0 | L27: =+K27 -> 0 | M27: =+L27 -> 0 | ... P27: =+O27 -> 0 | Q27: =+SUM(E27:P27) -> 0
B28: Marketing | C28: Engrain (Asset Intelligence) - One Time Set Up Cost | D28: No | E28: =+IF(D28="Yes",'Marketing List - Dropdowns'!$W$18,0) -> 0 | F28: 0 | G28: 0 | H28: 0 | I28: 0 | J28: 0 | K28: 0 | L28: 0 | M28: 0 | N28: 0 | O28: 0 | P28: 0 | Q28: =+SUM(E28:P28) -> 0
B29: Resident Retention | C29: Resident Retention/Prospect Experience | E29: 1250 | F29: =E29 -> 1250 | G29: =F29 -> 1250 | H29: =G29 -> 1250 | I29: =H29 -> 1250 | J29: =I29 -> 1250 | K29: =J29 -> 1250 | L29: =K29 -> 1250 | M29: =L29 -> 1250 | ... P29: =O29 -> 1250 | Q29: =+SUM(E29:P29) -> 15000
B30: Locator Fees | C30: Locators | E30: 500 | F30: =E30 -> 500 | G30: =F30 -> 500 | H30: =G30 -> 500 | I30: =H30 -> 500 | J30: =I30 -> 500 | K30: =J30 -> 500 | L30: =K30 -> 500 | M30: =L30 -> 500 | ... P30: =O30 -> 500 | Q30: =+SUM(E30:P30) -> 6000
B31: Marketing | Q31: =+SUM(E31:P31) -> 0
B32: Marketing | Q32: =+SUM(E32:P32) -> 0
B33: Marketing | Q33: =+SUM(E33:P33) -> 0
B34: Marketing | Q34: =+SUM(E34:P34) -> 0
B35: Marketing | Q35: =+SUM(E35:P35) -> 0
B36: Marketing | Q36: =+SUM(E36:P36) -> 0
B37: Marketing | Q37: =+SUM(E37:P37) -> 0
B38: Marketing | C38: Marketing Support Services | D38: 325 | E38: =$D$38 -> 325 | F38: =$D$38 -> 325 | G38: =$D$38 -> 325 | H38: =$D$38 -> 325 | I38: =$D$38 -> 325 | J38: =$D$38 -> 325 | K38: =$D$38 -> 325 | L38: =$D$38 -> 325 | ... P38: =$D$38 -> 325 | Q38: =+SUM(E38:P38) -> 3900
E39: =SUM(E6:E38) -> 7886 | F39: =SUM(F6:F38) -> 7486 | G39: =SUM(G6:G38) -> 7836 | H39: =SUM(H6:H38) -> 7486 | I39: =SUM(I6:I38) -> 7486 | J39: =SUM(J6:J38) -> 7836 | K39: =SUM(K6:K38) -> 7486 | L39: =SUM(L6:L38) -> 7486 | ... Q39: =SUM(Q6:Q38) -> 91632
Q41: =+Q39/B3 -> #DIV/0!
Q42: Per Unit

Sheet R&M Assumptions
B2: Total Number of Units
B3: ='Rent Schedule'!E31 -> 0
B5: Code | C5: Line Item | D5: Fixed Costs | E5: =+'Absorption Schedule'!I25 -> 46204 | F5: =EOMONTH(E5,1 ) -> 46265 | G5: =EOMONTH(F5,1 ) -> 46295 | H5: =EOMONTH(G5,1 ) -> 46326 | I5: =EOMONTH(H5,1 ) -> 46356 | J5: =EOMONTH(I5,1 ) -> 46387 | K5: =EOMONTH(J5,1 ) -> 46418 | L5: =EOMONTH(K5,1 ) -> 46446 | M5: =EOMONTH(L5,1 ) -> 46477 | ... P5: =EOMONTH(O5,1 ) -> 46568 | Q5: Total | R5: Comments
B6: R&M | C6: Appliances | Q6: =SUM(E6:P6) -> 0
B7: R&M | C7: Building | Q7: =SUM(E7:P7) -> 0
B8: R&M | C8: Electrical | Q8: =SUM(E8:P8) -> 0
B9: R&M | C9: Heating/AC | Q9: =SUM(E9:P9) -> 0
B10: R&M | C10: Plumbing | Q10: =SUM(E10:P10) -> 0
B11: R&M | C11: Maintenance - Equipment | Q11: =SUM(E11:P11) -> 0
B12: R&M | C12: Other Equipment | Q12: =SUM(E12:P12) -> 0
B13: R&M | C13: Security Access Gates | Q13: =SUM(E13:P13) -> 0
B14: R&M | C14: Fire Alarm Sprinkler | Q14: =SUM(E14:P14) -> 0
B15: R&M | C15: Pool | Q15: =SUM(E15:P15) -> 0
B16: Landscaping | C16: Landscaping (Seasonals) | Q16: =SUM(E16:P16) -> 0
B17: Landscaping | C17: Landscape (Mulch) | Q17: =SUM(E17:P17) -> 0
... B41: Make-Ready/Redec | C41: Window Coverings | Q41: =SUM(E41:P41) -> 0
Q42: =SUM(E42:P42) -> 0
Q43: =SUM(E43:P43) -> 0
Q44: =SUM(E44:P44) -> 0
Q45: =SUM(E45:P45) -> 0
Q46: =SUM(E46:P46) -> 0
Q47: =SUM(E47:P47) -> 0
Q48: =SUM(E48:P48) -> 0
Q49: =SUM(E49:P49) -> 0
Q50: =SUM(E50:P50) -> 0
Q51: =SUM(E51:P51) -> 0
Q52: =SUM(E52:P52) -> 0
Q53: =SUM(E53:P53) -> 0
... Q101: =SUM(E101:P101) -> 0
B103: xx | C103: Total | E103: =SUM(E6:E101) -> 0 | F103: =SUM(F6:F101) -> 0 | G103: =SUM(G6:G101) -> 0 | H103: =SUM(H6:H101) -> 0 | I103: =SUM(I6:I101) -> 0 | J103: =SUM(J6:J101) -> 0 | K103: =SUM(K6:K101) -> 0 | L103: =SUM(L6:L101) -> 0 | ... P103: =SUM(P6:P101) -> 0 | Q103: =SUM(E103:P103) -> 0
Q105: =+Q103/B3 -> #DIV/0!
Q106: Per Unit

Sheet Utilities Assumptions
B2: Total Number of Units
B3: ='Rent Schedule'!$E$21 -> 0
B5: Code | C5: Line Item | D5: =+'Absorption Schedule'!I25 -> 46204 | E5: =EOMONTH(D5,1 ) -> 46265 | F5: =EOMONTH(E5,1 ) -> 46295 | G5: =EOMONTH(F5,1 ) -> 46326 | H5: =EOMONTH(G5,1 ) -> 46356 | I5: =EOMONTH(H5,1 ) -> 46387 | J5: =EOMONTH(I5,1 ) -> 46418 | K5: =EOMONTH(J5,1 ) -> 46446 | L5: =EOMONTH(K5,1 ) -> 46477 | ... O5: =EOMONTH(N5,1 ) -> 46568 | P5: Total | Q5: Comments
B6: Utility Fees | C6: Utility Billing/UPM Fees | P6: =SUM(D6:O6) -> 0
B7: Electricity | C7: Electric | P7: =SUM(D7:O7) -> 0
B8: Electricity | C8: Electric - Vacant | P8: =SUM(D8:O8) -> 0
B9: Gas | C9: Gas | P9: =SUM(D9:O9) -> 0
B10: Water | C10: Water | P10: =SUM(D10:O10) -> 0
B11: Water | C11: Sewer | P11: =SUM(D11:O11) -> 0
B12: Water | C12: Water-Irrigation | P12: =SUM(D12:O12) -> 0
P13: =SUM(D13:O13) -> 0
P14: =SUM(D14:O14) -> 0
P15: =SUM(D15:O15) -> 0
P16: =SUM(D16:O16) -> 0
P17: =SUM(D17:O17) -> 0
P18: =SUM(D18:O18) -> 0
P19: =SUM(D19:O19) -> 0
P20: =SUM(D20:O20) -> 0
P21: =SUM(D21:O21) -> 0
P22: =SUM(D22:O22) -> 0
B24: xx | C24: Total | D24: =SUM(D6:D22) -> 0 | E24: =SUM(E6:E22) -> 0 | F24: =SUM(F6:F22) -> 0 | G24: =SUM(G6:G22) -> 0 | H24: =SUM(H6:H22) -> 0 | I24: =SUM(I6:I22) -> 0 | J24: =SUM(J6:J22) -> 0 | K24: =SUM(K6:K22) -> 0 | ... O24: =SUM(O6:O22) -> 0 | P24: =SUM(D24:O24) -> 0
P26: =+P24/B3 -> #DIV/0!
P27: Per Unit

Sheet Rent Schedule
C2: Morgan Rental Rate Review
C3: Unit Type | D3: Bedrooms | E3: Unit Count | F3: Net SF | G3: PPSF | H3: Occupied Units | I3: Exposure | J3: Market Rent | K3: Weeks | L3: Concessions | M3: Effective Rent | N3: Effective Rent/SF | P3: Annual Rent (Market) | R3: Current Market Rate | S3: Current Market Rate/SF | T3: Variance | U3: Current Effective Rate | V3: Current Effective Rate/SF | X3: Current Annual Rent (Market) | Z3: Increase/(Decrease) in Market Rent | AA3: Increase/(Decrease) in Effective Rent | AB3: Increase (Effective) | AD3: % of Units | AE3: Net SF | AF3: Projected Rent/SF | AG3: Market Rent | AH3: Concessions | AI3: Effective Rent | AJ3: Effective Rent/SF
I4: =IFERROR(1-(H4/E4),"") | J4: =F4*G4 -> 0 | L4: =-J4/52*K4 -> 0 | M4: =J4+L4 -> 0 | N4: =IFERROR(M4/F4,"") | P4: =+J4*E4*12 -> 0 | S4: =IFERROR(R4/F4,"") | T4: =IFERROR((R4-U4)/R4,"") | V4: =IFERROR(U4/F4,"") | X4: =IFERROR(S4*F4*E4*12,"") | Z4: =IFERROR((P4-X4)/X4,"") | AA4: =IFERROR((M4-U4)/U4,"") | AB4: =M4-U4 -> 0 | AD4: =IFERROR(E4/$E$31,"") | AE4: =IFERROR(AD4*F4,"") | AF4: =IFERROR(AD4*G4,"") | AG4: =IFERROR(AD4*J4,"") | AH4: =IFERROR(AD4*L4,"") | AI4: =IFERROR(AD4*M4,"") | AJ4: =IFERROR(AD4*N4,"")
I5: =IFERROR(1-(H5/E5),"") | J5: =F5*G5 -> 0 | L5: =-J5/52*K5 -> 0 | M5: =J5+L5 -> 0 | N5: =IFERROR(M5/F5,"") | P5: =+J5*E5*12 -> 0 | S5: =IFERROR(R5/F5,"") | T5: =IFERROR((R5-U5)/R5,"") | V5: =IFERROR(U5/F5,"") | X5: =IFERROR(S5*F5*E5*12,"") | Z5: =IFERROR((P5-X5)/X5,"") | AA5: =IFERROR((M5-U5)/U5,"") | AB5: =M5-U5 -> 0 | AD5: =IFERROR(E5/$E$31,"") | AE5: =IFERROR(AD5*F5,"") | AF5: =IFERROR(AD5*G5,"") | AG5: =IFERROR(AD5*J5,"") | AH5: =IFERROR(AD5*L5,"") | AI5: =IFERROR(AD5*M5,"") | AJ5: =IFERROR(AD5*N5,"")
I6: =IFERROR(1-(H6/E6),"") | J6: =F6*G6 -> 0 | L6: =-J6/52*K6 -> 0 | M6: =J6+L6 -> 0 | N6: =IFERROR(M6/F6,"") | P6: =+J6*E6*12 -> 0 | S6: =IFERROR(R6/F6,"") | T6: =IFERROR((R6-U6)/R6,"") | V6: =IFERROR(U6/F6,"") | X6: =IFERROR(S6*F6*E6*12,"") | Z6: =IFERROR((P6-X6)/X6,"") | AA6: =IFERROR((M6-U6)/U6,"") | AB6: =M6-U6 -> 0 | AD6: =IFERROR(E6/$E$31,"") | AE6: =IFERROR(AD6*F6,"") | AF6: =IFERROR(AD6*G6,"") | AG6: =IFERROR(AD6*J6,"") | AH6: =IFERROR(AD6*L6,"") | AI6: =IFERROR(AD6*M6,"") | AJ6: =IFERROR(AD6*N6,"")
I7: =IFERROR(1-(H7/E7),"") | J7: =F7*G7 -> 0 | L7: =-J7/52*K7 -> 0 | M7: =J7+L7 -> 0 | N7: =IFERROR(M7/F7,"") | P7: =+J7*E7*12 -> 0 | S7: =IFERROR(R7/F7,"") | T7: =IFERROR((R7-U7)/R7,"") | V7: =IFERROR(U7/F7,"") | X7: =IFERROR(S7*F7*E7*12,"") | Z7: =IFERROR((P7-X7)/X7,"") | AA7: =IFERROR((M7-U7)/U7,"") | AB7: =M7-U7 -> 0 | AD7: =IFERROR(E7/$E$31,"") | AE7: =IFERROR(AD7*F7,"") | AF7: =IFERROR(AD7*G7,"") | AG7: =IFERROR(AD7*J7,"") | AH7: =IFERROR(AD7*L7,"") | AI7: =IFERROR(AD7*M7,"") | AJ7: =IFERROR(AD7*N7,"")
I8: =IFERROR(1-(H8/E8),"") | J8: =F8*G8 -> 0 | L8: =-J8/52*K8 -> 0 | M8: =J8+L8 -> 0 | N8: =IFERROR(M8/F8,"") | P8: =+J8*E8*12 -> 0 | S8: =IFERROR(R8/F8,"") | T8: =IFERROR((R8-U8)/R8,"") | V8: =IFERROR(U8/F8,"") | X8: =IFERROR(S8*F8*E8*12,"") | Z8: =IFERROR((P8-X8)/X8,"") | AA8: =IFERROR((M8-U8)/U8,"") | AB8: =M8-U8 -> 0 | AD8: =IFERROR(E8/$E$31,"") | AE8: =IFERROR(AD8*F8,"") | AF8: =IFERROR(AD8*G8,"") | AG8: =IFERROR(AD8*J8,"") | AH8: =IFERROR(AD8*L8,"") | AI8: =IFERROR(AD8*M8,"") | AJ8: =IFERROR(AD8*N8,"")
I9: =IFERROR(1-(H9/E9),"") | J9: =F9*G9 -> 0 | L9: =-J9/52*K9 -> 0 | M9: =J9+L9 -> 0 | N9: =IFERROR(M9/F9,"") | P9: =+J9*E9*12 -> 0 | S9: =IFERROR(R9/F9,"") | T9: =IFERROR((R9-U9)/R9,"") | V9: =IFERROR(U9/F9,"") | X9: =IFERROR(S9*F9*E9*12,"") | Z9: =IFERROR((P9-X9)/X9,"") | AA9: =IFERROR((M9-U9)/U9,"") | AB9: =M9-U9 -> 0 | AD9: =IFERROR(E9/$E$31,"") | AE9: =IFERROR(AD9*F9,"") | AF9: =IFERROR(AD9*G9,"") | AG9: =IFERROR(AD9*J9,"") | AH9: =IFERROR(AD9*L9,"") | AI9: =IFERROR(AD9*M9,"") | AJ9: =IFERROR(AD9*N9,"")
I10: =IFERROR(1-(H10/E10),"") | J10: =F10*G10 -> 0 | L10: =-J10/52*K10 -> 0 | M10: =J10+L10 -> 0 | N10: =IFERROR(M10/F10,"") | P10: =+J10*E10*12 -> 0 | S10: =IFERROR(R10/F10,"") | T10: =IFERROR((R10-U10)/R10,"") | V10: =IFERROR(U10/F10,"") | X10: =IFERROR(S10*F10*E10*12,"") | Z10: =IFERROR((P10-X10)/X10,"") | AA10: =IFERROR((M10-U10)/U10,"") | AB10: =M10-U10 -> 0 | AD10: =IFERROR(E10/$E$31,"") | AE10: =IFERROR(AD10*F10,"") | AF10: =IFERROR(AD10*G10,"") | AG10: =IFERROR(AD10*J10,"") | AH10: =IFERROR(AD10*L10,"") | AI10: =IFERROR(AD10*M10,"") | AJ10: =IFERROR(AD10*N10,"")
I11: =IFERROR(1-(H11/E11),"") | J11: =F11*G11 -> 0 | L11: =-J11/52*K11 -> 0 | M11: =J11+L11 -> 0 | N11: =IFERROR(M11/F11,"") | P11: =+J11*E11*12 -> 0 | S11: =IFERROR(R11/F11,"") | T11: =IFERROR((R11-U11)/R11,"") | V11: =IFERROR(U11/F11,"") | X11: =IFERROR(S11*F11*E11*12,"") | Z11: =IFERROR((P11-X11)/X11,"") | AA11: =IFERROR((M11-U11)/U11,"") | AB11: =M11-U11 -> 0 | AD11: =IFERROR(E11/$E$31,"") | AE11: =IFERROR(AD11*F11,"") | AF11: =IFERROR(AD11*G11,"") | AG11: =IFERROR(AD11*J11,"") | AH11: =IFERROR(AD11*L11,"") | AI11: =IFERROR(AD11*M11,"") | AJ11: =IFERROR(AD11*N11,"")
I12: =IFERROR(1-(H12/E12),"") | J12: =F12*G12 -> 0 | L12: =-J12/52*K12 -> 0 | M12: =J12+L12 -> 0 | N12: =IFERROR(M12/F12,"") | P12: =+J12*E12*12 -> 0 | S12: =IFERROR(R12/F12,"") | T12: =IFERROR((R12-U12)/R12,"") | V12: =IFERROR(U12/F12,"") | X12: =IFERROR(S12*F12*E12*12,"") | Z12: =IFERROR((P12-X12)/X12,"") | AA12: =IFERROR((M12-U12)/U12,"") | AB12: =M12-U12 -> 0 | AD12: =IFERROR(E12/$E$31,"") | AE12: =IFERROR(AD12*F12,"") | AF12: =IFERROR(AD12*G12,"") | AG12: =IFERROR(AD12*J12,"") | AH12: =IFERROR(AD12*L12,"") | AI12: =IFERROR(AD12*M12,"") | AJ12: =IFERROR(AD12*N12,"")
I13: =IFERROR(1-(H13/E13),"") | J13: =F13*G13 -> 0 | L13: =-J13/52*K13 -> 0 | M13: =J13+L13 -> 0 | N13: =IFERROR(M13/F13,"") | P13: =+J13*E13*12 -> 0 | S13: =IFERROR(R13/F13,"") | T13: =IFERROR((R13-U13)/R13,"") | V13: =IFERROR(U13/F13,"") | X13: =IFERROR(S13*F13*E13*12,"") | Z13: =IFERROR((P13-X13)/X13,"") | AA13: =IFERROR((M13-U13)/U13,"") | AB13: =M13-U13 -> 0 | AD13: =IFERROR(E13/$E$31,"") | AE13: =IFERROR(AD13*F13,"") | AF13: =IFERROR(AD13*G13,"") | AG13: =IFERROR(AD13*J13,"") | AH13: =IFERROR(AD13*L13,"") | AI13: =IFERROR(AD13*M13,"") | AJ13: =IFERROR(AD13*N13,"")
I14: =IFERROR(1-(H14/E14),"") | J14: =F14*G14 -> 0 | L14: =-J14/52*K14 -> 0 | M14: =J14+L14 -> 0 | N14: =IFERROR(M14/F14,"") | P14: =+J14*E14*12 -> 0 | S14: =IFERROR(R14/F14,"") | T14: =IFERROR((R14-U14)/R14,"") | V14: =IFERROR(U14/F14,"") | X14: =IFERROR(S14*F14*E14*12,"") | Z14: =IFERROR((P14-X14)/X14,"") | AA14: =IFERROR((M14-U14)/U14,"") | AB14: =M14-U14 -> 0 | AD14: =IFERROR(E14/$E$31,"") | AE14: =IFERROR(AD14*F14,"") | AF14: =IFERROR(AD14*G14,"") | AG14: =IFERROR(AD14*J14,"") | AH14: =IFERROR(AD14*L14,"") | AI14: =IFERROR(AD14*M14,"") | AJ14: =IFERROR(AD14*N14,"")
I15: =IFERROR(1-(H15/E15),"") | J15: =F15*G15 -> 0 | L15: =-J15/52*K15 -> 0 | M15: =J15+L15 -> 0 | N15: =IFERROR(M15/F15,"") | P15: =+J15*E15*12 -> 0 | S15: =IFERROR(R15/F15,"") | T15: =IFERROR((R15-U15)/R15,"") | V15: =IFERROR(U15/F15,"") | X15: =IFERROR(S15*F15*E15*12,"") | Z15: =IFERROR((P15-X15)/X15,"") | AA15: =IFERROR((M15-U15)/U15,"") | AB15: =M15-U15 -> 0 | AD15: =IFERROR(E15/$E$31,"") | AE15: =IFERROR(AD15*F15,"") | AF15: =IFERROR(AD15*G15,"") | AG15: =IFERROR(AD15*J15,"") | AH15: =IFERROR(AD15*L15,"") | AI15: =IFERROR(AD15*M15,"") | AJ15: =IFERROR(AD15*N15,"")
... I30: =IFERROR(1-(H30/E30),"") | J30: =F30*G30 -> 0 | L30: =-J30/52*K30 -> 0 | M30: =J30+L30 -> 0 | N30: =IFERROR(M30/F30,"") | P30: =+J30*E30*12 -> 0 | S30: =IFERROR(R30/F30,"") | T30: =IFERROR((R30-U30)/R30,"") | V30: =IFERROR(U30/F30,"") | X30: =IFERROR(S30*F30*E30*12,"") | Z30: =IFERROR((P30-X30)/X30,"") | AA30: =IFERROR((M30-U30)/U30,"") | AB30: =M30-U30 -> 0 | AD30: =IFERROR(E30/$E$31,"") | AE30: =IFERROR(AD30*F30,"") | AF30: =IFERROR(AD30*G30,"") | AG30: =IFERROR(AD30*J30,"") | AH30: =IFERROR(AD30*L30,"") | AI30: =IFERROR(AD30*M30,"") | AJ30: =IFERROR(AD30*N30,"")
C31: Total | E31: =SUM(E4:E30) -> 0 | F31: =SUMPRODUCT(F4:F30,E4:E30)/E31 -> #DIV/0! | G31: =IFERROR(J31/F31,"") | H31: =SUM(H4:H30) -> 0 | I31: =IFERROR(SUMPRODUCT(I4:I30,E4:E30)/E31,0) -> 0 | J31: =+SUMPRODUCT(E4:E30,J4:J30)/E31 -> #DIV/0! | K31: =IFERROR(SUMPRODUCT(E4:E30,K4:K30)/E31,0) -> 0 | L31: =+SUMPRODUCT(E4:E30,L4:L30)/E31 -> #DIV/0! | M31: =+SUMPRODUCT(E4:E30,M4:M30)/E31 -> #DIV/0! | N31: =IFERROR(M31/F31,0) -> 0 | P31: =+SUM(P4:P30) -> 0 | R31: =IFERROR(SUMPRODUCT(R4:R30,E4:E30)/SUM(E4:E30),0) -> 0 | S31: =IFERROR(SUMPRODUCT(R4:R30,E4:E30)/SUMPRODUCT(E4:E30,F4:F30),0) -> 0 | T31: =IFERROR(SUMPRODUCT(H4:H30,T4:T30)/H31,0) -> 0 | U31: =IFERROR(SUMPRODUCT(U4:U30,H4:H30)/SUM(H4:H30),0) -> 0 | V31: =IFERROR(SUMPRODUCT(U4:U30,H4:H30)/SUMPRODUCT(H4:H30,F4:F30),0) -> 0 | X31: =SUM(X4:X30) -> 0 | Z31: =IFERROR((P31-X31)/X31,0) -> 0 | AA31: =IFERROR((M31-U31)/U31,0) -> 0 | AB31: =IFERROR(SUMPRODUCT(E4:E30,AB4:AB30)/E31,0) -> 0 | AD31: =SUM(AD4:AD30) -> 0 | AE31: =SUM(AE4:AE30) -> 0 | AF31: =SUM(AF4:AF30) -> 0 | AG31: =SUM(AG4:AG30) -> 0 | AH31: =SUM(AH4:AH30) -> 0 | AI31: =SUM(AI4:AI30) -> 0 | AJ31: =SUM(AJ4:AJ30) -> 0

Sheet Absorption Schedule
B3: Target Occupancy | C3: Min. Units
B4: 0.93 | C4: =B4*'Rent Schedule'!$E$31 -> 0
B5: Start Date | C5: Monthly Absorption
B6: 46204 | C6: =IFERROR(AVERAGE(I35:AF35),"") -> 15.958333
B7: Beginning Occupancy | C7: Closing Ratio
B8: 0 | C8: 0.25
B9: Concessions | C9: Retention
B10: 0 | C10: 0.5
E12: Max Lease Expirations | I12: =ROUND('[1]Rent Schedule'!$E$22* _xlfn.XLOOKUP( TEXT(IFERROR(DATEVALUE("1 "&I$25), I$25), "mmmm"), CapMonth, CapPct ), 0 ) -> #REF! | J12: =ROUND('[1]Rent Schedule'!$E$22* _xlfn.XLOOKUP( TEXT(IFERROR(DATEVALUE("1 "&J$25), J$25), "mmmm"), CapMonth, CapPct ), 0 ) -> #REF! | K12: =ROUND('[1]Rent Schedule'!$E$22* _xlfn.XLOOKUP( TEXT(IFERROR(DATEVALUE("1 "&K$25), K$25), "mmmm"), CapMonth, CapPct ), 0 ) -> #REF! | L12: =ROUND('[1]Rent Schedule'!$E$22* _xlfn.XLOOKUP( TEXT(IFERROR(DATEVALUE("1 "&L$25), L$25), "mmmm"), CapMonth, CapPct ), 0 ) -> #REF! | M12: =ROUND('[1]Rent Schedule'!$E$22* _xlfn.XLOOKUP( TEXT(IFERROR(DATEVALUE("1 "&M$25), M$25), "mmmm"), CapMonth, CapPct ), 0 ) -> #REF! | N12: =ROUND('[1]Rent Schedule'!$E$22* _xlfn.XLOOKUP( TEXT(IFERROR(DATEVALUE("1 "&N$25), N$25), "mmmm"), CapMonth, CapPct ), 0 ) -> #REF! | O12: =ROUND('[1]Rent Schedule'!$E$22* _xlfn.XLOOKUP( TEXT(IFERROR(DATEVALUE("1 "&O$25), O$25), "mmmm"), CapMonth, CapPct ), 0 ) -> #REF! | P12: =ROUND('[1]Rent Schedule'!$E$22* _xlfn.XLOOKUP( TEXT(IFERROR(DATEVALUE("1 "&P$25), P$25), "mmmm"), CapMonth, CapPct ), 0 ) -> #REF! | ... AZ12: =ROUND('[1]Rent Schedule'!$E$22* _xlfn.XLOOKUP( TEXT(IFERROR(DATEVALUE("1 "&AZ$25), AZ$25), "mmmm"), CapMonth, CapPct ), 0 ) -> #REF!
E13: Existing Lease Expirations | I13: 0 | J13: 0 | K13: 0 | L13: 0 | M13: 0 | N13: 0 | O13: 0 | P13: 0 | Q13: 0 | R13: 0 | S13: 0 | T13: 0 | U13: 0 | V13: 0 | W13: 0 | X13: 0 | Y13: 0 | Z13: 0 | AA13: 0 | AB13: 0 | AC13: 0 | AD13: 0 | AE13: 0 | AF13: 0 | AG13: 0 | AH13: 0 | AI13: 0 | AJ13: 0 | AK13: 0 | AL13: 0 | AM13: 0 | AN13: 0 | AO13: 0 | AP13: 0 | AQ13: 0 | AR13: 0 | AS13: 0 | AT13: 0 | AU13: 0 | AV13: 0 | AW13: 0 | AX13: 0 | AY13: 0 | AZ13: 0
E14: Remaining Lease Expirations | I14: =MAX(0, I12 - I13) -> #REF! | J14: =MAX(0, J12 - J13) -> #REF! | K14: =MAX(0, K12 - K13) -> #REF! | L14: =MAX(0, L12 - L13) -> #REF! | M14: =MAX(0, M12 - M13) -> #REF! | N14: =MAX(0, N12 - N13) -> #REF! | O14: =MAX(0, O12 - O13) -> #REF! | P14: =MAX(0, P12 - P13) -> #REF! | ... AZ14: =MAX(0, AZ12 - AZ13) -> #REF!
E16: {=_xlfn.SEQUENCE($BB$5-$BB$3+1,1,$BB$3,1)} -> 0 | I16: =IFERROR(OFFSET(I$14,0,$E$16),0) -> 0 | J16: =IFERROR(OFFSET(J$14,0,$E$16),0) -> 0 | K16: =IFERROR(OFFSET(K$14,0,$E$16),0) -> 0 | L16: =IFERROR(OFFSET(L$14,0,$E$16),0) -> 0 | M16: =IFERROR(OFFSET(M$14,0,$E$16),0) -> 0 | N16: =IFERROR(OFFSET(N$14,0,$E$16),0) -> 0 | O16: =IFERROR(OFFSET(O$14,0,$E$16),0) -> 0 | P16: =IFERROR(OFFSET(P$14,0,$E$16),0) -> 0 | ... AF16: =IFERROR(OFFSET(AF$14,0,$E$16),0) -> 0
I17: =IFERROR(OFFSET(I$14,0,$E$17),0) -> 0 | J17: =IFERROR(OFFSET(J$14,0,$E$17),0) -> 0 | K17: =IFERROR(OFFSET(K$14,0,$E$17),0) -> 0 | L17: =IFERROR(OFFSET(L$14,0,$E$17),0) -> 0 | M17: =IFERROR(OFFSET(M$14,0,$E$17),0) -> 0 | N17: =IFERROR(OFFSET(N$14,0,$E$17),0) -> 0 | O17: =IFERROR(OFFSET(O$14,0,$E$17),0) -> 0 | P17: =IFERROR(OFFSET(P$14,0,$E$17),0) -> 0 | ... AF17: =IFERROR(OFFSET(AF$14,0,$E$17),0) -> 0
I18: =IFERROR(OFFSET(I$14,0,$E$18),0) -> 0 | J18: =IFERROR(OFFSET(J$14,0,$E$18),0) -> 0 | K18: =IFERROR(OFFSET(K$14,0,$E$18),0) -> 0 | L18: =IFERROR(OFFSET(L$14,0,$E$18),0) -> 0 | M18: =IFERROR(OFFSET(M$14,0,$E$18),0) -> 0 | N18: =IFERROR(OFFSET(N$14,0,$E$18),0) -> 0 | O18: =IFERROR(OFFSET(O$14,0,$E$18),0) -> 0 | P18: =IFERROR(OFFSET(P$14,0,$E$18),0) -> 0 | ... AF18: =IFERROR(OFFSET(AF$14,0,$E$18),0) -> 0
I19: =IFERROR(OFFSET(I$14,0,$E$19),0) -> 0 | J19: =IFERROR(OFFSET(J$14,0,$E$19),0) -> 0 | K19: =IFERROR(OFFSET(K$14,0,$E$19),0) -> 0 | L19: =IFERROR(OFFSET(L$14,0,$E$19),0) -> 0 | M19: =IFERROR(OFFSET(M$14,0,$E$19),0) -> 0 | N19: =IFERROR(OFFSET(N$14,0,$E$19),0) -> 0 | O19: =IFERROR(OFFSET(O$14,0,$E$19),0) -> 0 | P19: =IFERROR(OFFSET(P$14,0,$E$19),0) -> 0 | ... AF19: =IFERROR(OFFSET(AF$14,0,$E$19),0) -> 0
I20: =IFERROR(OFFSET(I$14,0,$E$20),0) -> 0 | J20: =IFERROR(OFFSET(J$14,0,$E$20),0) -> 0 | K20: =IFERROR(OFFSET(K$14,0,$E$20),0) -> 0 | L20: =IFERROR(OFFSET(L$14,0,$E$20),0) -> 0 | M20: =IFERROR(OFFSET(M$14,0,$E$20),0) -> 0 | N20: =IFERROR(OFFSET(N$14,0,$E$20),0) -> 0 | O20: =IFERROR(OFFSET(O$14,0,$E$20),0) -> 0 | P20: =IFERROR(OFFSET(P$14,0,$E$20),0) -> 0 | ... AF20: =IFERROR(OFFSET(AF$14,0,$E$20),0) -> 0
I21: =IFERROR(OFFSET(I$14,0,$E$21),0) -> 0 | J21: =IFERROR(OFFSET(J$14,0,$E$21),0) -> 0 | K21: =IFERROR(OFFSET(K$14,0,$E$21),0) -> 0 | L21: =IFERROR(OFFSET(L$14,0,$E$21),0) -> 0 | M21: =IFERROR(OFFSET(M$14,0,$E$21),0) -> 0 | N21: =IFERROR(OFFSET(N$14,0,$E$21),0) -> 0 | O21: =IFERROR(OFFSET(O$14,0,$E$21),0) -> 0 | P21: =IFERROR(OFFSET(P$14,0,$E$21),0) -> 0 | ... AF21: =IFERROR(OFFSET(AF$14,0,$E$21),0) -> 0
I23: 0 | J23: 0 | K23: =MAX(0, MIN(J16, I$32 - MIN(I$32, SUM($J16:J$21)))) -> 0 | L23: =SUMIFS($J$16:$J$21,$I$16:$I$21,L$14) -> 0 | M23: =SUMIFS($J$16:$J$21,$I$16:$I$21,M$14) -> 0 | N23: =SUMIFS($J$16:$J$21,$I$16:$I$21,N$14) -> 0 | O23: =SUMIFS($J$16:$J$21,$I$16:$I$21,O$14) -> 0 | P23: =SUMIFS($J$16:$J$21,$I$16:$I$21,P$14) -> 0 | Q23: =SUMIFS($J$16:$J$21,$I$16:$I$21,Q$14) -> 0 | R23: =SUMIFS($J$16:$J$21,$I$16:$I$21,R$14) -> 0 | S23: =SUMIFS($J$16:$J$21,$I$16:$I$21,S$14) -> 0 | ... AF23: =SUMIFS($J$16:$J$21,$I$16:$I$21,AF$14) -> 0
F24: Pre-Leasing
E25: Month | F25: =EOMONTH(G25,-1) -> 46142 | G25: =EOMONTH(H25,-1) -> 46173 | H25: =EOMONTH(I25,-1) -> 46203 | I25: =+B6 -> 46204 | J25: =EOMONTH(I25,1) -> 46265 | K25: =EOMONTH(J25,1) -> 46295 | L25: =EOMONTH(K25,1) -> 46326 | M25: =EOMONTH(L25,1) -> 46356 | N25: =EOMONTH(M25,1) -> 46387 | O25: =EOMONTH(N25,1) -> 46418 | P25: =EOMONTH(O25,1) -> 46446 | Q25: =EOMONTH(P25,1) -> 46477 | ... AZ25: =EOMONTH(AY25,1) -> 47542
E27: Lease Expirations
E28: Move-Outs | I28: =ROUNDUP((1-I29)*I27,0) -> 0 | J28: =ROUNDUP((1-J29)*J27,0) -> 0 | K28: =ROUNDUP((1-K29)*K27,0) -> 0 | L28: =ROUNDUP(L27*$C$10,0) -> 0 | M28: =ROUNDUP(M27*$C$10,0) -> 0 | N28: =ROUNDUP(N27*$C$10,0) -> 0 | O28: =ROUNDUP(O27*$C$10,0) -> 0 | P28: =ROUNDUP(P27*$C$10,0) -> 0 | Q28: =ROUNDUP(Q27*$C$10,0) -> 0 | R28: =ROUNDUP(R27*$C$10,0) -> 0 | S28: =ROUNDUP(S27*$C$10,0) -> 0 | ... AF28: =ROUNDUP(AF27*$C$10,0) -> 0
E29: Retention Ratio (Transition) | I29: 0.4 | J29: 0.4 | K29: 0.4
E31: Assumed Traffic | I31: 80 | J31: 90 | K31: 90 | L31: 85 | M31: 70 | N31: 70 | O31: 75 | P31: 75 | Q31: 75 | R31: 75 | S31: 75 | T31: 75 | U31: 75 | V31: 85 | W31: 50 | X31: 55 | Y31: 55 | Z31: 60 | AA31: 60 | AB31: 55 | AC31: 50 | AD31: 40 | AE31: 30 | AF31: 30
E32: New Leases | I32: =ROUNDDOWN($C$8*I31,0) -> 20 | J32: =ROUNDDOWN($C$8*J31,0) -> 22 | K32: =ROUNDDOWN($C$8*K31,0) -> 22 | L32: =ROUNDDOWN($C$8*L31,0) -> 21 | M32: =ROUNDDOWN($C$8*M31,0) -> 17 | N32: =ROUNDDOWN($C$8*N31,0) -> 17 | O32: =ROUNDDOWN($C$8*O31,0) -> 18 | P32: =ROUNDDOWN($C$8*P31,0) -> 18 | ... AF32: =ROUNDDOWN($C$8*AF31,0) -> 7
E35: Net Leases | I35: =I32-I28 -> 20 | J35: =J32-J28 -> 22 | K35: =K32-K28 -> 22 | L35: =L32-L28 -> 21 | M35: =M32-M28 -> 17 | N35: =N32-N28 -> 17 | O35: =O32-O28 -> 18 | P35: =P32-P28 -> 18 | ... AF35: =AF32-AF28 -> 7
E37: Occupied Units | H37: =ROUNDUP((1+'Proforma (Annual)'!N15)*'Proforma (Annual)'!C4,0) -> #DIV/0! | I37: =+H37 -> #DIV/0! | J37: =+I37+I35 -> #DIV/0! | K37: =+J37+J35 -> #DIV/0! | L37: =+K37+K35 -> #DIV/0! | M37: =+L37+L35 -> #DIV/0! | N37: =+M37+M35 -> #DIV/0! | O37: =+N37+N35 -> #DIV/0! | P37: =+O37+O35 -> #DIV/0! | Q37: =+P37+P35 -> #DIV/0! | ... T37: =+S37+S35 -> #DIV/0! | U37: =+T37+U35 -> #DIV/0! | V37: =+U37+V35 -> #DIV/0! | W37: =+V37+W35 -> #DIV/0! | X37: =+W37+X35 -> #DIV/0! | Y37: =+X37+Y35 -> #DIV/0! | Z37: =+Y37+Z35 -> #DIV/0! | AA37: =+Z37+AA35 -> #DIV/0! | AB37: =+AA37+AB35 -> #DIV/0! | ... AF37: =+AE37+AF35 -> #DIV/0!
E38: Total Units | I38: =+C4/B4 -> 0 | J38: =+I38 -> 0 | K38: =+J38 -> 0 | L38: =+K38 -> 0 | M38: =+L38 -> 0 | N38: =+M38 -> 0 | O38: =+N38 -> 0 | P38: =+O38 -> 0 | Q38: =+P38 -> 0 | ... AF38: =+AE38 -> 0
E39: Anticipated Occupancy | I39: =+I37/I38 -> #DIV/0! | J39: =+J37/J38 -> #DIV/0! | K39: =+K37/K38 -> #DIV/0! | L39: =+L37/L38 -> #DIV/0! | M39: =+M37/M38 -> #DIV/0! | N39: =+N37/N38 -> #DIV/0! | O39: =+O37/O38 -> #DIV/0! | P39: =+P37/P38 -> #DIV/0! | ... AF39: =+AF37/AF38 -> #DIV/0!
E41: Concessions | I41: =IFERROR(I37*$B$10,0) -> 0 | J41: =IFERROR(J37*$B$10,0) -> 0 | K41: =IFERROR(K37*$B$10,0) -> 0 | L41: =IFERROR(L37*$B$10,0) -> 0 | M41: =IFERROR(M37*$B$10,0) -> 0 | N41: =IFERROR(N37*$B$10,0) -> 0 | O41: =IFERROR(O37*$B$10,0) -> 0 | P41: =IFERROR(P37*$B$10,0) -> 0 | ... AF41: =IFERROR(AF37*$B$10,0) -> 0
I43: Retention Ratio during transition is projected at 40%. Renewals go out roughly 60 days prior to lease expiration, thus assuming a July transition, August and September renewals will have been distributed at a minimum. We are assuming a lower than average renewal ratio for this period.
I45: Closing ratio of 22% is projected based on our portfolio.
I46: Lease Expirations are based on current rent roll. This analysis does not project early terminations.

Sheet OUTPUTS

Sheet Proforma (Annual)
C1: Property Name
C2: ='T-12 Inputs'!C2 -> 0
C3: Units
C4: ='Rent Schedule'!E31 -> 0
E6: =CONCATENATE(C2,"- Annualized Financials") -> 0- Annualized Financials | R6: Owner Budget | U6: Morgan Underwriting | X6: Underwriting Notes
E7: Trailing - 12 | H7: Ann. Trailing - 6 | K7: Ann. Trailing - 3 | N7: Ann. Trailing - 1
E8: $ | F8: $/Unit | H8: $ | I8: $/Unit | K8: $ | L8: $/Unit | N8: $ | O8: $/Unit | R8: $ | S8: $/Unit | V8: $ | W8: $/Unit
C10: Market Rent | E10: {=+SUMPRODUCT('T-12 Inputs'!$D$7:$O$100*('T-12 Inputs'!$A$7:$A$100='OpStatement List - Dropdowns'!$I$5))} -> 0 | F10: =+E10/$C$4 -> #DIV/0! | H10: {=+SUMPRODUCT('T-12 Inputs'!$J$7:$O$100*('T-12 Inputs'!$A$7:$A$100='OpStatement List - Dropdowns'!$I$5))*2} -> 0 | I10: =+H10/$C$4 -> #DIV/0! | K10: {=+SUMPRODUCT('T-12 Inputs'!$M$7:$O$100*('T-12 Inputs'!$A$7:$A$100='OpStatement List - Dropdowns'!$I$5))*4} -> 0 | L10: =+K10/$C$4 -> #DIV/0! | N10: {=+SUMPRODUCT('T-12 Inputs'!$O$7:$O$100*('T-12 Inputs'!$A$7:$A$100='OpStatement List - Dropdowns'!$I$5))*12} -> 0 | O10: =+N10/$C$4 -> #DIV/0! | V10: =+E10 -> 0 | W10: =+V10/$C$4 -> #DIV/0!
C11: Loss to Lease | E11: {=+SUMPRODUCT('T-12 Inputs'!$D$7:$O$100*('T-12 Inputs'!$A$7:$A$100='OpStatement List - Dropdowns'!$I$6))} -> 0 | F11: =+E11/$C$4 -> #DIV/0! | H11: {=+SUMPRODUCT('T-12 Inputs'!$J$7:$O$100*('T-12 Inputs'!$A$7:$A$100='OpStatement List - Dropdowns'!$I$6))*2} -> 0 | I11: =+H11/$C$4 -> #DIV/0! | K11: {=+SUMPRODUCT('T-12 Inputs'!$M$7:$O$100*('T-12 Inputs'!$A$7:$A$100='OpStatement List - Dropdowns'!$I$6))*4} -> 0 | L11: =+K11/$C$4 -> #DIV/0! | N11: {=+SUMPRODUCT('T-12 Inputs'!$O$7:$O$100*('T-12 Inputs'!$A$7:$A$100='OpStatement List - Dropdowns'!$I$6))*12} -> 0 | O11: =+N11/$C$4 -> #DIV/0! | V11: =+V10*-U11 -> 0 | W11: =+V11/$C$4 -> #DIV/0!
C12: Gross Potential Rent | E12: =+SUM(E10:E11) -> 0 | F12: =+E12/$C$4 -> #DIV/0! | H12: =+SUM(H10:H11) -> 0 | I12: =+H12/$C$4 -> #DIV/0! | K12: =+SUM(K10:K11) -> 0 | L12: =+K12/$C$4 -> #DIV/0! | N12: =+SUM(N10:N11) -> 0 | O12: =+N12/$C$4 -> #DIV/0! | R12: =+SUM(R10:R11) -> 0 | S12: =+R12/C4 -> #DIV/0! | V12: =+SUM(V10:V11) -> 0 | W12: =+V12/$C$4 -> #DIV/0!
C14: Vacancy | E14: {=+SUMPRODUCT('T-12 Inputs'!$D$7:$O$100*('T-12 Inputs'!$A$7:$A$100='OpStatement List - Dropdowns'!$I$7))} -> 0 | F14: =+E14/$C$4 -> #DIV/0! | H14: {=+SUMPRODUCT('T-12 Inputs'!$J$7:$O$100*('T-12 Inputs'!$A$7:$A$100='OpStatement List - Dropdowns'!$I$7))*2} -> 0 | I14: =+H14/$C$4 -> #DIV/0! | K14: {=+SUMPRODUCT('T-12 Inputs'!$M$7:$O$100*('T-12 Inputs'!$A$7:$A$100='OpStatement List - Dropdowns'!I7))*4} -> 0 | L14: =+K14/$C$4 -> #DIV/0! | N14: {=+SUMPRODUCT('T-12 Inputs'!$O$7:$O$100*('T-12 Inputs'!$A$7:$A$100='OpStatement List - Dropdowns'!I7))*12} -> 0 | O14: =+N14/$C$4 -> #DIV/0! | S14: =+R14/$C$4 -> #DIV/0! | V14: =+U14*-$V$12 -> 0 | W14: =+V14/$C$4 -> #DIV/0!
C15: Vacancy (%) | E15: =+E14/E12 -> #DIV/0! | H15: =+H14/H12 -> #DIV/0! | K15: =+K14/K12 -> #DIV/0! | N15: =+N14/N12 -> #DIV/0!
C16: Concessions | E16: {=+SUMPRODUCT('T-12 Inputs'!$D$7:$O$100*('T-12 Inputs'!$A$7:$A$100='OpStatement List - Dropdowns'!$I$8))} -> 0 | F16: =+E16/$C$4 -> #DIV/0! | H16: {=+SUMPRODUCT('T-12 Inputs'!$J$7:$O$100*('T-12 Inputs'!$A$7:$A$100='OpStatement List - Dropdowns'!$I$8))*2} -> 0 | I16: =+H16/$C$4 -> #DIV/0! | K16: {=+SUMPRODUCT('T-12 Inputs'!$M$7:$O$100*('T-12 Inputs'!$A$7:$A$100='OpStatement List - Dropdowns'!I8))*4} -> 0 | L16: =+K16/$C$4 -> #DIV/0! | N16: {=+SUMPRODUCT('T-12 Inputs'!$O$7:$O$100*('T-12 Inputs'!$A$7:$A$100='OpStatement List - Dropdowns'!I8))*12} -> 0 | O16: =+N16/$C$4 -> #DIV/0! | S16: =+R16/$C$4 -> #DIV/0! | V16: =+U16*-$V$12 -> 0 | W16: =+V16/$C$4 -> #DIV/0!
C17: Bad Debt | E17: {=+SUMPRODUCT('T-12 Inputs'!$D$7:$O$100*('T-12 Inputs'!$A$7:$A$100='OpStatement List - Dropdowns'!$I$9))} -> 0 | F17: =+E17/$C$4 -> #DIV/0! | H17: {=+SUMPRODUCT('T-12 Inputs'!$J$7:$O$100*('T-12 Inputs'!$A$7:$A$100='OpStatement List - Dropdowns'!$I$9))*2} -> 0 | I17: =+H17/$C$4 -> #DIV/0! | K17: {=+SUMPRODUCT('T-12 Inputs'!$M$7:$O$100*('T-12 Inputs'!$A$7:$A$100='OpStatement List - Dropdowns'!I9))*4} -> 0 | L17: =+K17/$C$4 -> #DIV/0! | N17: {=+SUMPRODUCT('T-12 Inputs'!$O$7:$O$100*('T-12 Inputs'!$A$7:$A$100='OpStatement List - Dropdowns'!I9))*12} -> 0 | O17: =+N17/$C$4 -> #DIV/0! | S17: =+R17/$C$4 -> #DIV/0! | V17: =+U17*-$V$12 -> 0 | W17: =+V17/$C$4 -> #DIV/0!
C18: Model/Employee Discount | E18: {=+SUMPRODUCT('T-12 Inputs'!$D$7:$O$100*('T-12 Inputs'!$A$7:$A$100='OpStatement List - Dropdowns'!$I$10))} -> 0 | F18: =+E18/$C$4 -> #DIV/0! | H18: {=+SUMPRODUCT('T-12 Inputs'!$J$7:$O$100*('T-12 Inputs'!$A$7:$A$100='OpStatement List - Dropdowns'!$I$10))*2} -> 0 | I18: =+H18/$C$4 -> #DIV/0! | K18: {=+SUMPRODUCT('T-12 Inputs'!$M$7:$O$100*('T-12 Inputs'!$A$7:$A$100='OpStatement List - Dropdowns'!I10))*4} -> 0 | L18: =+K18/$C$4 -> #DIV/0! | N18: {=+SUMPRODUCT('T-12 Inputs'!$O$7:$O$100*('T-12 Inputs'!$A$7:$A$100='OpStatement List - Dropdowns'!I10))*12} -> 0 | O18: =+N18/$C$4 -> #DIV/0! | S18: =+R18/$C$4 -> #DIV/0! | U18: =-V18/V12 -> #DIV/0! | V18: =-12*1.7*'Rent Schedule'!J31 -> #DIV/0! | W18: =+V18/$C$4 -> #DIV/0!
C19: Economic Vacancy | E19: =+SUM(E16:E18,E14) -> 0 | F19: =SUM(F14:F17) -> #DIV/0! | H19: =+SUM(H16:H18,H14) -> 0 | I19: =SUM(I14:I17) -> #DIV/0! | K19: =+SUM(K16:K18,K14) -> 0 | L19: =SUM(L14:L17) -> #DIV/0! | N19: =+SUM(N16:N18,N14) -> 0 | O19: =SUM(O14:O17) -> #DIV/0! | R19: =SUM(R14:R18) -> 0 | S19: =SUM(S14:S17) -> #DIV/0! | V19: =SUM(V14:V18) -> #DIV/0! | W19: =+V19/$C$4 -> #DIV/0!
C21: Total Rental Income | E21: =+SUM(E12,E19) -> 0 | F21: =+E21/$C$4 -> #DIV/0! | H21: =+SUM(H12,H19) -> 0 | I21: =+H21/$C$4 -> #DIV/0! | K21: =+SUM(K12,K19) -> 0 | L21: =+K21/$C$4 -> #DIV/0! | N21: =+SUM(N12,N19) -> 0 | O21: =+N21/$C$4 -> #DIV/0! | R21: =+R12+R19 -> 0 | S21: =+R21/$C$4 -> #DIV/0! | V21: =+SUM(V12,V19) -> #DIV/0! | W21: =+V21/$C$4 -> #DIV/0!
C23: Administrative Fees | E23: {=+SUMPRODUCT('T-12 Inputs'!$D$7:$O$100*('T-12 Inputs'!$A$7:$A$100=C23))} -> 0 | F23: =+E23/$C$4 -> #DIV/0! | H23: {=+SUMPRODUCT('T-12 Inputs'!$J$7:$O$100*('T-12 Inputs'!$A$7:$A$100=C23))*2} -> 0 | I23: =+H23/$C$4 -> #DIV/0! | K23: {=+SUMPRODUCT('T-12 Inputs'!$M$7:$O$100*('T-12 Inputs'!$A$7:$A$100=C23))*4} -> 0 | L23: =+K23/$C$4 -> #DIV/0! | N23: {=+SUMPRODUCT('T-12 Inputs'!$O$7:$O$100*('T-12 Inputs'!$A$7:$A$100=C23))*12} -> 0 | O23: =+N23/$C$4 -> #DIV/0! | W23: =+V23/$C$4 -> #DIV/0!
